Workbook

Sheet PrDeparture
A3: Player B | D3: V | E3: V | F3: V | G3: V | H3: E | I3: E | J3: E | K3: O | L3: O | M3: L
A4: Player C | D4: V | E4: E | F4: O | G4: L | H4: E | I4: O | J4: L | K4: O | L4: L | M4: L
A5: Player A | B5: V | C5: P(V) | D5: 0.33 | E5: 0.5 | F5: 0.5 | G5: 0.5 | H5: 1 | I5: 1 | J5: 1 | K5: 1 | L5: 1 | M5: 1
C6: P(E) | D6: 0.33 | E6: 0.5 | F6: 0.5 | G6: 0.5 | H6: 0 | I6: 0 | J6: 0 | K6: 0 | L6: 0 | M6: 0
C7: P(O) | D7: 0.33 | E7: 0 | F7: 0 | G7: 0 | H7: 0 | I7: 0 | J7: 0 | K7: 0 | L7: 0 | M7: 0
C8: P(L) | D8: 0 | E8: 0 | F8: 0 | G8: 0 | H8: 0 | I8: 0 | J8: 0 | K8: 0 | L8: 0 | M8: 0
C9: P(_R) | D9: 0 | E9: 0 | F9: 0 | G9: 0 | H9: 0 | I9: 0 | J9: 0 | K9: 0 | L9: 0 | M9: 0
C10: P(S) | D10: 0 | E10: 0 | F10: 0 | G10: 0 | H10: 0 | I10: 0 | J10: 0 | K10: 0 | L10: 0 | M10: 0
B11: E | C11: P(V) | D11: 0 | E11: 0 | F11: 0 | G11: 0 | H11: 0 | I11: 0 | J11: 0 | K11: 0 | L11: 0 | M11: 0
C12: P(E) | D12: 0 | E12: 0.5 | F12: 1 | G12: 1 | H12: 0.33 | I12: 0.5 | J12: 0.5 | K12: 1 | L12: 1 | M12: 1
C13: P(O) | D13: 1 | E13: 0.5 | F13: 0 | G13: 0 | H13: 0.33 | I13: 0.5 | J13: 0.5 | K13: 0 | L13: 0 | M13: 0
C14: P(L) | D14: 0 | E14: 0 | F14: 0 | G14: 0 | H14: 0.33 | I14: 0 | J14: 0 | K14: 0 | L14: 0 | M14: 0
C15: P(_R) | D15: 0 | E15: 0 | F15: 0 | G15: 0 | H15: 0 | I15: 0 | J15: 0 | K15: 0 | L15: 0 | M15: 0
C16: P(S) | D16: 0 | E16: 0 | F16: 0 | G16: 0 | H16: 0 | I16: 0 | J16: 0 | K16: 0 | L16: 0 | M16: 0
B17: O | C17: P(V) | D17: 0 | E17: 0 | F17: 0 | G17: 0 | H17: 0 | I17: 0 | J17: 0 | K17: 0 | L17: 0 | M17: 0
C18: P(E) | D18: 0 | E18: 0 | F18: 0 | G18: 0 | H18: 0 | I18: 0 | J18: 0 | K18: 0 | L18: 0 | M18: 0
C19: P(O) | D19: 1 | E19: 1 | F19: 0.5 | G19: 1 | H19: 0 | I19: 0.5 | J19: 1 | K19: 0.33 | L19: 0.5 | M19: 1
C20: P(L) | D20: 0 | E20: 0 | F20: 0.5 | G20: 0 | H20: 1 | I20: 0.5 | J20: 0 | K20: 0.33 | L20: 0.5 | M20: 0
C21: P(_R) | D21: 0 | E21: 0 | F21: 0 | G21: 0 | H21: 0 | I21: 0 | J21: 0 | K21: 0.33 | L21: 0 | M21: 0
C22: P(S) | D22: 0 | E22: 0 | F22: 0 | G22: 0 | H22: 0 | I22: 0 | J22: 0 | K22: 0 | L22: 0 | M22: 0
B23: L | C23: P(V) | D23: 0 | E23: 0 | F23: 0 | G23: 0 | H23: 0 | I23: 0 | J23: 0 | K23: 0 | L23: 0 | M23: 0
C24: P(E) | D24: 0 | E24: 0 | F24: 0 | G24: 0 | H24: 0 | I24: 0 | J24: 0 | K24: 0 | L24: 0 | M24: 0
C25: P(O) | D25: 0 | E25: 0 | F25: 0 | G25: 0 | H25: 0 | I25: 0 | J25: 0 | K25: 0 | L25: 0 | M25: 0
C26: P(L) | D26: 1 | E26: 1 | F26: 1 | G26: 0.5 | H26: 1 | I26: 1 | J26: 0.5 | K26: 0 | L26: 0.5 | M26: 0.33
C27: P(_R) | D27: 0 | E27: 0 | F27: 0 | G27: 0.5 | H27: 0 | I27: 0 | J27: 0 | K27: 1 | L27: 0.5 | M27: 0.33
C28: P(S) | D28: 0 | E28: 0 | F28: 0 | G28: 0 | H28: 0 | I28: 0 | J28: 0 | K28: 0 | L28: 0 | M28: 0.33

Sheet Parameters
A1: VeryEarly | B1: 3 | D1: Number of Nash Equilibria (Unpriced) | E1: E,D,L | F1: Number of Nash Equilibria (Unpriced) | G1: Solutions | H1: Number of Nash Equilibria (Priced) | I1: Solutions | J1: LowestTC
A2: Early | B2: 3 | D2: =Master!AW67 -> 1 | E2: 0,0,0 | F2: 64 | G2: all | H2: 64 | I2: all | J2: 0
A3: Ontime | B3: 0 | D3: Number of Nash Equilibria (MC priced) | E3: 0,1,0 | F3: 24 | G3: VEO …, VEL …, VOL …, EOL … , | H3: 24 | I3: VEO …, VEL …, VOL …, EOL … , | J3: 0
A4: Delay | B4: 1 | D4: =Master!BM67 -> 3 | E4: 0,0,1 | F4: 13 | G4: VVV, VVO …, VEE … , VEO, … | H4: 13 | I4: VVV, VVO …, VEE … , VEO, … | J4: 0
A5: Late | B5: 4 | D5: Minimum TC | E5: 0,1,1 | F5: 6 | G5: VEO, … | H5: 6 | I5: VEO, … | J5: 0
D6: =Master!AY67 -> 7 | E6: 1,0,0 | F6: 8 | G6: OOO,LLL,OLL, …, OOL … | H6: 8 | I6: OOO,LLL,LLO, …, OOL … | J6: 0
A7: V=Very Early | E7: 1,1,0 | F7: 7 | G7: OOO, OOL …, OLL, … | H7: 3 | I7: LLO, … | J7: 1 | K7: (others at 1 not Nash)
A8: E - Early | E8: 1,0,1 | F8: 5 | G8: OOO, EEE, … EOO, … | H8: 4 | I8: EEE, EEO, … | J8: 2
A9: O = Ontime | E9: 1,1,1 | F9: 9 | G9: EOL, … , EOO, … | H9: 6 | I9: EOL, … | J9: 2
A10: L=Late | E10: 3,1,4 | F10: 1 | G10: EEE | H10: 3 | I10: EOO, … | J10: 7
A11: R=Really Late | E11: 4,0,3 | F11: 2 | G11: OOO, EEE | H11: 4 | I11: EEE, EOO | J11: 7
A12: S=Super Late | E12: 4,1,3 | F12: 4 | G12: OOO, EOO, ... | H12: 9 | I12: EOL, …, EOO | J12: 7
E13: 3,0,4 | F13: 1 | G13: EEE | H13: 1 | I13: EEE | J13: 7
A16: Tree
A17: Arrival Pattern | B17: Departure Pattern | C17: VEO | D17: VEL | E17: VOL | F17: VLR | G17: EOL | H17: ELR | I17: OLR | J17: LRS | L17: VEO
A18: VVV | B18: VEO | C18: =IF($B18=C$17,1,0) -> 1 | D18: =IF($B18=D$17,1,0) -> 0 | E18: =IF($B18=E$17,1,0) -> 0 | F18: =IF($B18=F$17,1,0) -> 0 | G18: =IF($B18=G$17,1,0) -> 0 | H18: =IF($B18=H$17,1,0) -> 0 | I18: =IF($B18=I$17,1,0) -> 0 | J18: =IF($B18=J$17,1,0) -> 0 | L18: VEL
A19: VVE | B19: VEO | C19: =IF($B19=C$17,1,0) -> 1 | D19: =IF($B19=D$17,1,0) -> 0 | E19: =IF($B19=E$17,1,0) -> 0 | F19: =IF($B19=F$17,1,0) -> 0 | G19: =IF($B19=G$17,1,0) -> 0 | H19: =IF($B19=H$17,1,0) -> 0 | I19: =IF($B19=I$17,1,0) -> 0 | J19: =IF($B19=J$17,1,0) -> 0 | L19: VOL
A20: VVO | B20: VEO | C20: =IF($B20=C$17,1,0) -> 1 | D20: =IF($B20=D$17,1,0) -> 0 | E20: =IF($B20=E$17,1,0) -> 0 | F20: =IF($B20=F$17,1,0) -> 0 | G20: =IF($B20=G$17,1,0) -> 0 | H20: =IF($B20=H$17,1,0) -> 0 | I20: =IF($B20=I$17,1,0) -> 0 | J20: =IF($B20=J$17,1,0) -> 0 | L20: VLR
A21: VVL | B21: VEL | C21: =IF($B21=C$17,1,0) -> 0 | D21: =IF($B21=D$17,1,0) -> 1 | E21: =IF($B21=E$17,1,0) -> 0 | F21: =IF($B21=F$17,1,0) -> 0 | G21: =IF($B21=G$17,1,0) -> 0 | H21: =IF($B21=H$17,1,0) -> 0 | I21: =IF($B21=I$17,1,0) -> 0 | J21: =IF($B21=J$17,1,0) -> 0 | L21: EOL
A22: VEV | B22: VEO | C22: =IF($B22=C$17,1,0) -> 1 | D22: =IF($B22=D$17,1,0) -> 0 | E22: =IF($B22=E$17,1,0) -> 0 | F22: =IF($B22=F$17,1,0) -> 0 | G22: =IF($B22=G$17,1,0) -> 0 | H22: =IF($B22=H$17,1,0) -> 0 | I22: =IF($B22=I$17,1,0) -> 0 | J22: =IF($B22=J$17,1,0) -> 0 | L22: ELR
A23: VEE | B23: VEO | C23: =IF($B23=C$17,1,0) -> 1 | D23: =IF($B23=D$17,1,0) -> 0 | E23: =IF($B23=E$17,1,0) -> 0 | F23: =IF($B23=F$17,1,0) -> 0 | G23: =IF($B23=G$17,1,0) -> 0 | H23: =IF($B23=H$17,1,0) -> 0 | I23: =IF($B23=I$17,1,0) -> 0 | J23: =IF($B23=J$17,1,0) -> 0 | L23: OLR
A24: VEO | B24: VEO | C24: =IF($B24=C$17,1,0) -> 1 | D24: =IF($B24=D$17,1,0) -> 0 | E24: =IF($B24=E$17,1,0) -> 0 | F24: =IF($B24=F$17,1,0) -> 0 | G24: =IF($B24=G$17,1,0) -> 0 | H24: =IF($B24=H$17,1,0) -> 0 | I24: =IF($B24=I$17,1,0) -> 0 | J24: =IF($B24=J$17,1,0) -> 0 | L24: LRS
A25: VEL | B25: VEL | C25: =IF($B25=C$17,1,0) -> 0 | D25: =IF($B25=D$17,1,0) -> 1 | E25: =IF($B25=E$17,1,0) -> 0 | F25: =IF($B25=F$17,1,0) -> 0 | G25: =IF($B25=G$17,1,0) -> 0 | H25: =IF($B25=H$17,1,0) -> 0 | I25: =IF($B25=I$17,1,0) -> 0 | J25: =IF($B25=J$17,1,0) -> 0
A26: VOV | B26: VEO | C26: =IF($B26=C$17,1,0) -> 1 | D26: =IF($B26=D$17,1,0) -> 0 | E26: =IF($B26=E$17,1,0) -> 0 | F26: =IF($B26=F$17,1,0) -> 0 | G26: =IF($B26=G$17,1,0) -> 0 | H26: =IF($B26=H$17,1,0) -> 0 | I26: =IF($B26=I$17,1,0) -> 0 | J26: =IF($B26=J$17,1,0) -> 0
A27: VOE | B27: VEO | C27: =IF($B27=C$17,1,0) -> 1 | D27: =IF($B27=D$17,1,0) -> 0 | E27: =IF($B27=E$17,1,0) -> 0 | F27: =IF($B27=F$17,1,0) -> 0 | G27: =IF($B27=G$17,1,0) -> 0 | H27: =IF($B27=H$17,1,0) -> 0 | I27: =IF($B27=I$17,1,0) -> 0 | J27: =IF($B27=J$17,1,0) -> 0
A28: VOO | B28: VOL | C28: =IF($B28=C$17,1,0) -> 0 | D28: =IF($B28=D$17,1,0) -> 0 | E28: =IF($B28=E$17,1,0) -> 1 | F28: =IF($B28=F$17,1,0) -> 0 | G28: =IF($B28=G$17,1,0) -> 0 | H28: =IF($B28=H$17,1,0) -> 0 | I28: =IF($B28=I$17,1,0) -> 0 | J28: =IF($B28=J$17,1,0) -> 0
A29: VOL | B29: VOL | C29: =IF($B29=C$17,1,0) -> 0 | D29: =IF($B29=D$17,1,0) -> 0 | E29: =IF($B29=E$17,1,0) -> 1 | F29: =IF($B29=F$17,1,0) -> 0 | G29: =IF($B29=G$17,1,0) -> 0 | H29: =IF($B29=H$17,1,0) -> 0 | I29: =IF($B29=I$17,1,0) -> 0 | J29: =IF($B29=J$17,1,0) -> 0
A30: VLV | B30: VEL | C30: =IF($B30=C$17,1,0) -> 0 | D30: =IF($B30=D$17,1,0) -> 1 | E30: =IF($B30=E$17,1,0) -> 0 | F30: =IF($B30=F$17,1,0) -> 0 | G30: =IF($B30=G$17,1,0) -> 0 | H30: =IF($B30=H$17,1,0) -> 0 | I30: =IF($B30=I$17,1,0) -> 0 | J30: =IF($B30=J$17,1,0) -> 0
A31: VLE | B31: VEL | C31: =IF($B31=C$17,1,0) -> 0 | D31: =IF($B31=D$17,1,0) -> 1 | E31: =IF($B31=E$17,1,0) -> 0 | F31: =IF($B31=F$17,1,0) -> 0 | G31: =IF($B31=G$17,1,0) -> 0 | H31: =IF($B31=H$17,1,0) -> 0 | I31: =IF($B31=I$17,1,0) -> 0 | J31: =IF($B31=J$17,1,0) -> 0
A32: VLO | B32: VOL | C32: =IF($B32=C$17,1,0) -> 0 | D32: =IF($B32=D$17,1,0) -> 0 | E32: =IF($B32=E$17,1,0) -> 1 | F32: =IF($B32=F$17,1,0) -> 0 | G32: =IF($B32=G$17,1,0) -> 0 | H32: =IF($B32=H$17,1,0) -> 0 | I32: =IF($B32=I$17,1,0) -> 0 | J32: =IF($B32=J$17,1,0) -> 0
A33: VLL | B33: VLR | C33: =IF($B33=C$17,1,0) -> 0 | D33: =IF($B33=D$17,1,0) -> 0 | E33: =IF($B33=E$17,1,0) -> 0 | F33: =IF($B33=F$17,1,0) -> 1 | G33: =IF($B33=G$17,1,0) -> 0 | H33: =IF($B33=H$17,1,0) -> 0 | I33: =IF($B33=I$17,1,0) -> 0 | J33: =IF($B33=J$17,1,0) -> 0
A34: EVV | B34: VEO | C34: =IF($B34=C$17,1,0) -> 1 | D34: =IF($B34=D$17,1,0) -> 0 | E34: =IF($B34=E$17,1,0) -> 0 | F34: =IF($B34=F$17,1,0) -> 0 | G34: =IF($B34=G$17,1,0) -> 0 | H34: =IF($B34=H$17,1,0) -> 0 | I34: =IF($B34=I$17,1,0) -> 0 | J34: =IF($B34=J$17,1,0) -> 0
A35: EVE | B35: VEO | C35: =IF($B35=C$17,1,0) -> 1 | D35: =IF($B35=D$17,1,0) -> 0 | E35: =IF($B35=E$17,1,0) -> 0 | F35: =IF($B35=F$17,1,0) -> 0 | G35: =IF($B35=G$17,1,0) -> 0 | H35: =IF($B35=H$17,1,0) -> 0 | I35: =IF($B35=I$17,1,0) -> 0 | J35: =IF($B35=J$17,1,0) -> 0
A36: EVO | B36: VEO | C36: =IF($B36=C$17,1,0) -> 1 | D36: =IF($B36=D$17,1,0) -> 0 | E36: =IF($B36=E$17,1,0) -> 0 | F36: =IF($B36=F$17,1,0) -> 0 | G36: =IF($B36=G$17,1,0) -> 0 | H36: =IF($B36=H$17,1,0) -> 0 | I36: =IF($B36=I$17,1,0) -> 0 | J36: =IF($B36=J$17,1,0) -> 0
... A81: LLL | B81: LRS | C81: =IF($B81=C$17,1,0) -> 0 | D81: =IF($B81=D$17,1,0) -> 0 | E81: =IF($B81=E$17,1,0) -> 0 | F81: =IF($B81=F$17,1,0) -> 0 | G81: =IF($B81=G$17,1,0) -> 0 | H81: =IF($B81=H$17,1,0) -> 0 | I81: =IF($B81=I$17,1,0) -> 0 | J81: =IF($B81=J$17,1,0) -> 1
C83: =SUM(C18:C81) -> 16 | D83: =SUM(D18:D81) -> 9 | E83: =SUM(E18:E81) -> 9 | F83: =SUM(F18:F81) -> 3 | G83: =SUM(G18:G81) -> 16 | H83: =SUM(H18:H81) -> 3 | I83: =SUM(I18:I81) -> 7 | J83: =SUM(J18:J81) -> 1 | K83: =SUM(C83:J83) -> 64

Sheet TwoPlayers
A1: Vehicle A | B1: Vehicle B | C1: V | D1: E | E1: O | F1: L | G1: AV | H1: AE | I1: AO | J1: AL | K1: BV | L1: BE | M1: BO | N1: BL | O1: QLV | P1: QLE | Q1: QLO | R1: QLL | S1: E(Delay A) | T1: E(Delay B) | U1: E(ArrivalTimeA) | V1: E(ArrivalTimeB) | W1: ArrA1 | X1: ArrA2 | Y1: ArrA3 | Z1: ArrB1 | AA1: ArrB2 | AB1: ArrB3 | AC1: E(SD A) | AD1: E(SD B) | AE1: Price A | AF1: Price B | AG1: PATTERN | AH1: TC
A2: V | B2: V | C2: =(IF($A2="V",1,0))+IF($B2="V",1,0) -> 2 | D2: =(IF($A2="E",1,0))+IF($B2="E",1,0) -> 0 | E2: =(IF($A2="O",1,0))+IF($B2="O",1,0) -> 0 | F2: =(IF($A2="L",1,0))+IF($B2="L",1,0) -> 0 | G2: =(IF(A2="V",1,0)) -> 1 | H2: =(IF(A2="E",1,0)) -> 0 | I2: =(IF(A2="O",1,0)) -> 0 | J2: =(IF(A2="L",1,0)) -> 0 | K2: =(IF(B2="V",1,0)) -> 1 | L2: =(IF(B2="E",1,0)) -> 0 | M2: =(IF(B2="O",1,0)) -> 0 | N2: =(IF(B2="L",1,0)) -> 0 | O2: =MAX(C2-1,0) -> 1 | P2: =MAX(O2-1+D2,0) -> 0 | Q2: =MAX(P2-1+E2,0) -> 0 | R2: =MAX(Q2-1+F2,0) -> 0 | S2: =0.5*($O2*G2+$P2*H2+$Q2*I2+$R2*J2) -> 0.5 | T2: =0.5*($O2*K2+$P2*L2+$Q2*M2+$R2*N2) -> 0.5 | U2: =IF(A2="V",-2,0)+IF(A2="E",-1,0)+IF(A2="O",0,0)+IF(A2="L",1,0)+S2 -> -1.5 | V2: =IF(B2="V",-2,0)+IF(B2="E",-1,0)+IF(B2="O",0,0)+IF(B2="L",1,0)+T2 -> -1.5 | W2: =IF(A2="V",-2,0)+IF(A2="E",-1,0)+IF(A2="O",0,0)+IF(A2="L",1,0) -> -2 | X2: =IF(A2="V",-2,0)+IF(A2="E",-1,0)+IF(A2="O",0,0)+IF(A2="L",1,0)+S2 -> -1.5 | Y2: =IF(A2="V",-2,0)+IF(A2="E",-1,0)+IF(A2="O",0,0)+IF(A2="L",1,0)+S2*2 -> -1 | Z2: =IF(B2="V",-2,0)+IF(B2="E",-1,0)+IF(B2="O",0,0)+IF(B2="L",1,0) -> -2 | AA2: =IF(B2="V",-2,0)+IF(B2="E",-1,0)+IF(B2="O",0,0)+IF(B2="L",1,0)+T2 -> -1.5 | AB2: =IF(B2="V",-2,0)+IF(B2="E",-1,0)+IF(B2="O",0,0)+IF(B2="L",1,0)+T2*2 -> -1 | AC2: =(ABS(IF(W2<0,W2*Early,W2*Late))+ABS(IF(X2<0,X2*Early,X2*Late))+ABS(IF(Y2<0,Y2*Early,Y2*Late)))/3 -> 4.5 | AD2: =(ABS(IF(Z2<0,Z2*Early,Z2*Late))+ABS(IF(AA2<0,AA2*Early,AA2*Late))+ABS(IF(AB2<0,AB2*Early,AB2*Late)))/3 -> 4.5 | AE2: =S2*Delay+AC2 -> 5 | AF2: =T2*Delay+AD2 -> 5 | AG2: =A2&B2 -> VV | AH2: =AE2+AF2 -> 10
A3: V | B3: E | C3: =(IF($A3="V",1,0))+IF($B3="V",1,0) -> 1 | D3: =(IF($A3="E",1,0))+IF($B3="E",1,0) -> 1 | E3: =(IF($A3="O",1,0))+IF($B3="O",1,0) -> 0 | F3: =(IF($A3="L",1,0))+IF($B3="L",1,0) -> 0 | G3: =(IF(A3="V",1,0)) -> 1 | H3: =(IF(A3="E",1,0)) -> 0 | I3: =(IF(A3="O",1,0)) -> 0 | J3: =(IF(A3="L",1,0)) -> 0 | K3: =(IF(B3="V",1,0)) -> 0 | L3: =(IF(B3="E",1,0)) -> 1 | M3: =(IF(B3="O",1,0)) -> 0 | N3: =(IF(B3="L",1,0)) -> 0 | O3: =MAX(C3-1,0) -> 0 | P3: =MAX(O3-1+D3,0) -> 0 | Q3: =MAX(P3-1+E3,0) -> 0 | R3: =MAX(Q3-1+F3,0) -> 0 | S3: =0.5*($O3*G3+$P3*H3+$Q3*I3+$R3*J3) -> 0 | T3: =0.5*($O3*K3+$P3*L3+$Q3*M3+$R3*N3) -> 0 | U3: =IF(A3="V",-2,0)+IF(A3="E",-1,0)+IF(A3="O",0,0)+IF(A3="L",1,0)+S3 -> -2 | V3: =IF(B3="V",-2,0)+IF(B3="E",-1,0)+IF(B3="O",0,0)+IF(B3="L",1,0)+T3 -> -1 | W3: =IF(A3="V",-2,0)+IF(A3="E",-1,0)+IF(A3="O",0,0)+IF(A3="L",1,0) -> -2 | X3: =IF(A3="V",-2,0)+IF(A3="E",-1,0)+IF(A3="O",0,0)+IF(A3="L",1,0)+S3 -> -2 | Y3: =IF(A3="V",-2,0)+IF(A3="E",-1,0)+IF(A3="O",0,0)+IF(A3="L",1,0)+S3*2 -> -2 | Z3: =IF(B3="V",-2,0)+IF(B3="E",-1,0)+IF(B3="O",0,0)+IF(B3="L",1,0) -> -1 | AA3: =IF(B3="V",-2,0)+IF(B3="E",-1,0)+IF(B3="O",0,0)+IF(B3="L",1,0)+T3 -> -1 | AB3: =IF(B3="V",-2,0)+IF(B3="E",-1,0)+IF(B3="O",0,0)+IF(B3="L",1,0)+T3*2 -> -1 | AC3: =(ABS(IF(W3<0,W3*Early,W3*Late))+ABS(IF(X3<0,X3*Early,X3*Late))+ABS(IF(Y3<0,Y3*Early,Y3*Late)))/3 -> 6 | AD3: =(ABS(IF(Z3<0,Z3*Early,Z3*Late))+ABS(IF(AA3<0,AA3*Early,AA3*Late))+ABS(IF(AB3<0,AB3*Early,AB3*Late)))/3 -> 3 | AE3: =S3*Delay+AC3 -> 6 | AF3: =T3*Delay+AD3 -> 3 | AG3: =A3&B3 -> VE | AH3: =AE3+AF3 -> 9
A4: V | B4: O | C4: =(IF($A4="V",1,0))+IF($B4="V",1,0) -> 1 | D4: =(IF($A4="E",1,0))+IF($B4="E",1,0) -> 0 | E4: =(IF($A4="O",1,0))+IF($B4="O",1,0) -> 1 | F4: =(IF($A4="L",1,0))+IF($B4="L",1,0) -> 0 | G4: =(IF(A4="V",1,0)) -> 1 | H4: =(IF(A4="E",1,0)) -> 0 | I4: =(IF(A4="O",1,0)) -> 0 | J4: =(IF(A4="L",1,0)) -> 0 | K4: =(IF(B4="V",1,0)) -> 0 | L4: =(IF(B4="E",1,0)) -> 0 | M4: =(IF(B4="O",1,0)) -> 1 | N4: =(IF(B4="L",1,0)) -> 0 | O4: =MAX(C4-1,0) -> 0 | P4: =MAX(O4-1+D4,0) -> 0 | Q4: =MAX(P4-1+E4,0) -> 0 | R4: =MAX(Q4-1+F4,0) -> 0 | S4: =0.5*($O4*G4+$P4*H4+$Q4*I4+$R4*J4) -> 0 | T4: =0.5*($O4*K4+$P4*L4+$Q4*M4+$R4*N4) -> 0 | U4: =IF(A4="V",-2,0)+IF(A4="E",-1,0)+IF(A4="O",0,0)+IF(A4="L",1,0)+S4 -> -2 | V4: =IF(B4="V",-2,0)+IF(B4="E",-1,0)+IF(B4="O",0,0)+IF(B4="L",1,0)+T4 -> 0 | W4: =IF(A4="V",-2,0)+IF(A4="E",-1,0)+IF(A4="O",0,0)+IF(A4="L",1,0) -> -2 | X4: =IF(A4="V",-2,0)+IF(A4="E",-1,0)+IF(A4="O",0,0)+IF(A4="L",1,0)+S4 -> -2 | Y4: =IF(A4="V",-2,0)+IF(A4="E",-1,0)+IF(A4="O",0,0)+IF(A4="L",1,0)+S4*2 -> -2 | Z4: =IF(B4="V",-2,0)+IF(B4="E",-1,0)+IF(B4="O",0,0)+IF(B4="L",1,0) -> 0 | AA4: =IF(B4="V",-2,0)+IF(B4="E",-1,0)+IF(B4="O",0,0)+IF(B4="L",1,0)+T4 -> 0 | AB4: =IF(B4="V",-2,0)+IF(B4="E",-1,0)+IF(B4="O",0,0)+IF(B4="L",1,0)+T4*2 -> 0 | AC4: =(ABS(IF(W4<0,W4*Early,W4*Late))+ABS(IF(X4<0,X4*Early,X4*Late))+ABS(IF(Y4<0,Y4*Early,Y4*Late)))/3 -> 6 | AD4: =(ABS(IF(Z4<0,Z4*Early,Z4*Late))+ABS(IF(AA4<0,AA4*Early,AA4*Late))+ABS(IF(AB4<0,AB4*Early,AB4*Late)))/3 -> 0 | AE4: =S4*Delay+AC4 -> 6 | AF4: =T4*Delay+AD4 -> 0 | AG4: =A4&B4 -> VO | AH4: =AE4+AF4 -> 6
A5: V | B5: L | C5: =(IF($A5="V",1,0))+IF($B5="V",1,0) -> 1 | D5: =(IF($A5="E",1,0))+IF($B5="E",1,0) -> 0 | E5: =(IF($A5="O",1,0))+IF($B5="O",1,0) -> 0 | F5: =(IF($A5="L",1,0))+IF($B5="L",1,0) -> 1 | G5: =(IF(A5="V",1,0)) -> 1 | H5: =(IF(A5="E",1,0)) -> 0 | I5: =(IF(A5="O",1,0)) -> 0 | J5: =(IF(A5="L",1,0)) -> 0 | K5: =(IF(B5="V",1,0)) -> 0 | L5: =(IF(B5="E",1,0)) -> 0 | M5: =(IF(B5="O",1,0)) -> 0 | N5: =(IF(B5="L",1,0)) -> 1 | O5: =MAX(C5-1,0) -> 0 | P5: =MAX(O5-1+D5,0) -> 0 | Q5: =MAX(P5-1+E5,0) -> 0 | R5: =MAX(Q5-1+F5,0) -> 0 | S5: =0.5*($O5*G5+$P5*H5+$Q5*I5+$R5*J5) -> 0 | T5: =0.5*($O5*K5+$P5*L5+$Q5*M5+$R5*N5) -> 0 | U5: =IF(A5="V",-2,0)+IF(A5="E",-1,0)+IF(A5="O",0,0)+IF(A5="L",1,0)+S5 -> -2 | V5: =IF(B5="V",-2,0)+IF(B5="E",-1,0)+IF(B5="O",0,0)+IF(B5="L",1,0)+T5 -> 1 | W5: =IF(A5="V",-2,0)+IF(A5="E",-1,0)+IF(A5="O",0,0)+IF(A5="L",1,0) -> -2 | X5: =IF(A5="V",-2,0)+IF(A5="E",-1,0)+IF(A5="O",0,0)+IF(A5="L",1,0)+S5 -> -2 | Y5: =IF(A5="V",-2,0)+IF(A5="E",-1,0)+IF(A5="O",0,0)+IF(A5="L",1,0)+S5*2 -> -2 | Z5: =IF(B5="V",-2,0)+IF(B5="E",-1,0)+IF(B5="O",0,0)+IF(B5="L",1,0) -> 1 | AA5: =IF(B5="V",-2,0)+IF(B5="E",-1,0)+IF(B5="O",0,0)+IF(B5="L",1,0)+T5 -> 1 | AB5: =IF(B5="V",-2,0)+IF(B5="E",-1,0)+IF(B5="O",0,0)+IF(B5="L",1,0)+T5*2 -> 1 | AC5: =(ABS(IF(W5<0,W5*Early,W5*Late))+ABS(IF(X5<0,X5*Early,X5*Late))+ABS(IF(Y5<0,Y5*Early,Y5*Late)))/3 -> 6 | AD5: =(ABS(IF(Z5<0,Z5*Early,Z5*Late))+ABS(IF(AA5<0,AA5*Early,AA5*Late))+ABS(IF(AB5<0,AB5*Early,AB5*Late)))/3 -> 4 | AE5: =S5*Delay+AC5 -> 6 | AF5: =T5*Delay+AD5 -> 4 | AG5: =A5&B5 -> VL | AH5: =AE5+AF5 -> 10
A6: E | B6: V | C6: =(IF($A6="V",1,0))+IF($B6="V",1,0) -> 1 | D6: =(IF($A6="E",1,0))+IF($B6="E",1,0) -> 1 | E6: =(IF($A6="O",1,0))+IF($B6="O",1,0) -> 0 | F6: =(IF($A6="L",1,0))+IF($B6="L",1,0) -> 0 | G6: =(IF(A6="V",1,0)) -> 0 | H6: =(IF(A6="E",1,0)) -> 1 | I6: =(IF(A6="O",1,0)) -> 0 | J6: =(IF(A6="L",1,0)) -> 0 | K6: =(IF(B6="V",1,0)) -> 1 | L6: =(IF(B6="E",1,0)) -> 0 | M6: =(IF(B6="O",1,0)) -> 0 | N6: =(IF(B6="L",1,0)) -> 0 | O6: =MAX(C6-1,0) -> 0 | P6: =MAX(O6-1+D6,0) -> 0 | Q6: =MAX(P6-1+E6,0) -> 0 | R6: =MAX(Q6-1+F6,0) -> 0 | S6: =0.5*($O6*G6+$P6*H6+$Q6*I6+$R6*J6) -> 0 | T6: =0.5*($O6*K6+$P6*L6+$Q6*M6+$R6*N6) -> 0 | U6: =IF(A6="V",-2,0)+IF(A6="E",-1,0)+IF(A6="O",0,0)+IF(A6="L",1,0)+S6 -> -1 | V6: =IF(B6="V",-2,0)+IF(B6="E",-1,0)+IF(B6="O",0,0)+IF(B6="L",1,0)+T6 -> -2 | W6: =IF(A6="V",-2,0)+IF(A6="E",-1,0)+IF(A6="O",0,0)+IF(A6="L",1,0) -> -1 | X6: =IF(A6="V",-2,0)+IF(A6="E",-1,0)+IF(A6="O",0,0)+IF(A6="L",1,0)+S6 -> -1 | Y6: =IF(A6="V",-2,0)+IF(A6="E",-1,0)+IF(A6="O",0,0)+IF(A6="L",1,0)+S6*2 -> -1 | Z6: =IF(B6="V",-2,0)+IF(B6="E",-1,0)+IF(B6="O",0,0)+IF(B6="L",1,0) -> -2 | AA6: =IF(B6="V",-2,0)+IF(B6="E",-1,0)+IF(B6="O",0,0)+IF(B6="L",1,0)+T6 -> -2 | AB6: =IF(B6="V",-2,0)+IF(B6="E",-1,0)+IF(B6="O",0,0)+IF(B6="L",1,0)+T6*2 -> -2 | AC6: =(ABS(IF(W6<0,W6*Early,W6*Late))+ABS(IF(X6<0,X6*Early,X6*Late))+ABS(IF(Y6<0,Y6*Early,Y6*Late)))/3 -> 3 | AD6: =(ABS(IF(Z6<0,Z6*Early,Z6*Late))+ABS(IF(AA6<0,AA6*Early,AA6*Late))+ABS(IF(AB6<0,AB6*Early,AB6*Late)))/3 -> 6 | AE6: =S6*Delay+AC6 -> 3 | AF6: =T6*Delay+AD6 -> 6 | AG6: =A6&B6 -> EV | AH6: =AE6+AF6 -> 9
A7: E | B7: E | C7: =(IF($A7="V",1,0))+IF($B7="V",1,0) -> 0 | D7: =(IF($A7="E",1,0))+IF($B7="E",1,0) -> 2 | E7: =(IF($A7="O",1,0))+IF($B7="O",1,0) -> 0 | F7: =(IF($A7="L",1,0))+IF($B7="L",1,0) -> 0 | G7: =(IF(A7="V",1,0)) -> 0 | H7: =(IF(A7="E",1,0)) -> 1 | I7: =(IF(A7="O",1,0)) -> 0 | J7: =(IF(A7="L",1,0)) -> 0 | K7: =(IF(B7="V",1,0)) -> 0 | L7: =(IF(B7="E",1,0)) -> 1 | M7: =(IF(B7="O",1,0)) -> 0 | N7: =(IF(B7="L",1,0)) -> 0 | O7: =MAX(C7-1,0) -> 0 | P7: =MAX(O7-1+D7,0) -> 1 | Q7: =MAX(P7-1+E7,0) -> 0 | R7: =MAX(Q7-1+F7,0) -> 0 | S7: =0.5*($O7*G7+$P7*H7+$Q7*I7+$R7*J7) -> 0.5 | T7: =0.5*($O7*K7+$P7*L7+$Q7*M7+$R7*N7) -> 0.5 | U7: =IF(A7="V",-2,0)+IF(A7="E",-1,0)+IF(A7="O",0,0)+IF(A7="L",1,0)+S7 -> -0.5 | V7: =IF(B7="V",-2,0)+IF(B7="E",-1,0)+IF(B7="O",0,0)+IF(B7="L",1,0)+T7 -> -0.5 | W7: =IF(A7="V",-2,0)+IF(A7="E",-1,0)+IF(A7="O",0,0)+IF(A7="L",1,0) -> -1 | X7: =IF(A7="V",-2,0)+IF(A7="E",-1,0)+IF(A7="O",0,0)+IF(A7="L",1,0)+S7 -> -0.5 | Y7: =IF(A7="V",-2,0)+IF(A7="E",-1,0)+IF(A7="O",0,0)+IF(A7="L",1,0)+S7*2 -> 0 | Z7: =IF(B7="V",-2,0)+IF(B7="E",-1,0)+IF(B7="O",0,0)+IF(B7="L",1,0) -> -1 | AA7: =IF(B7="V",-2,0)+IF(B7="E",-1,0)+IF(B7="O",0,0)+IF(B7="L",1,0)+T7 -> -0.5 | AB7: =IF(B7="V",-2,0)+IF(B7="E",-1,0)+IF(B7="O",0,0)+IF(B7="L",1,0)+T7*2 -> 0 | AC7: =(ABS(IF(W7<0,W7*Early,W7*Late))+ABS(IF(X7<0,X7*Early,X7*Late))+ABS(IF(Y7<0,Y7*Early,Y7*Late)))/3 -> 1.5 | AD7: =(ABS(IF(Z7<0,Z7*Early,Z7*Late))+ABS(IF(AA7<0,AA7*Early,AA7*Late))+ABS(IF(AB7<0,AB7*Early,AB7*Late)))/3 -> 1.5 | AE7: =S7*Delay+AC7 -> 2 | AF7: =T7*Delay+AD7 -> 2 | AG7: =A7&B7 -> EE | AH7: =AE7+AF7 -> 4
A8: E | B8: O | C8: =(IF($A8="V",1,0))+IF($B8="V",1,0) -> 0 | D8: =(IF($A8="E",1,0))+IF($B8="E",1,0) -> 1 | E8: =(IF($A8="O",1,0))+IF($B8="O",1,0) -> 1 | F8: =(IF($A8="L",1,0))+IF($B8="L",1,0) -> 0 | G8: =(IF(A8="V",1,0)) -> 0 | H8: =(IF(A8="E",1,0)) -> 1 | I8: =(IF(A8="O",1,0)) -> 0 | J8: =(IF(A8="L",1,0)) -> 0 | K8: =(IF(B8="V",1,0)) -> 0 | L8: =(IF(B8="E",1,0)) -> 0 | M8: =(IF(B8="O",1,0)) -> 1 | N8: =(IF(B8="L",1,0)) -> 0 | O8: =MAX(C8-1,0) -> 0 | P8: =MAX(O8-1+D8,0) -> 0 | Q8: =MAX(P8-1+E8,0) -> 0 | R8: =MAX(Q8-1+F8,0) -> 0 | S8: =0.5*($O8*G8+$P8*H8+$Q8*I8+$R8*J8) -> 0 | T8: =0.5*($O8*K8+$P8*L8+$Q8*M8+$R8*N8) -> 0 | U8: =IF(A8="V",-2,0)+IF(A8="E",-1,0)+IF(A8="O",0,0)+IF(A8="L",1,0)+S8 -> -1 | V8: =IF(B8="V",-2,0)+IF(B8="E",-1,0)+IF(B8="O",0,0)+IF(B8="L",1,0)+T8 -> 0 | W8: =IF(A8="V",-2,0)+IF(A8="E",-1,0)+IF(A8="O",0,0)+IF(A8="L",1,0) -> -1 | X8: =IF(A8="V",-2,0)+IF(A8="E",-1,0)+IF(A8="O",0,0)+IF(A8="L",1,0)+S8 -> -1 | Y8: =IF(A8="V",-2,0)+IF(A8="E",-1,0)+IF(A8="O",0,0)+IF(A8="L",1,0)+S8*2 -> -1 | Z8: =IF(B8="V",-2,0)+IF(B8="E",-1,0)+IF(B8="O",0,0)+IF(B8="L",1,0) -> 0 | AA8: =IF(B8="V",-2,0)+IF(B8="E",-1,0)+IF(B8="O",0,0)+IF(B8="L",1,0)+T8 -> 0 | AB8: =IF(B8="V",-2,0)+IF(B8="E",-1,0)+IF(B8="O",0,0)+IF(B8="L",1,0)+T8*2 -> 0 | AC8: =(ABS(IF(W8<0,W8*Early,W8*Late))+ABS(IF(X8<0,X8*Early,X8*Late))+ABS(IF(Y8<0,Y8*Early,Y8*Late)))/3 -> 3 | AD8: =(ABS(IF(Z8<0,Z8*Early,Z8*Late))+ABS(IF(AA8<0,AA8*Early,AA8*Late))+ABS(IF(AB8<0,AB8*Early,AB8*Late)))/3 -> 0 | AE8: =S8*Delay+AC8 -> 3 | AF8: =T8*Delay+AD8 -> 0 | AG8: =A8&B8 -> EO | AH8: =AE8+AF8 -> 3
A9: E | B9: L | C9: =(IF($A9="V",1,0))+IF($B9="V",1,0) -> 0 | D9: =(IF($A9="E",1,0))+IF($B9="E",1,0) -> 1 | E9: =(IF($A9="O",1,0))+IF($B9="O",1,0) -> 0 | F9: =(IF($A9="L",1,0))+IF($B9="L",1,0) -> 1 | G9: =(IF(A9="V",1,0)) -> 0 | H9: =(IF(A9="E",1,0)) -> 1 | I9: =(IF(A9="O",1,0)) -> 0 | J9: =(IF(A9="L",1,0)) -> 0 | K9: =(IF(B9="V",1,0)) -> 0 | L9: =(IF(B9="E",1,0)) -> 0 | M9: =(IF(B9="O",1,0)) -> 0 | N9: =(IF(B9="L",1,0)) -> 1 | O9: =MAX(C9-1,0) -> 0 | P9: =MAX(O9-1+D9,0) -> 0 | Q9: =MAX(P9-1+E9,0) -> 0 | R9: =MAX(Q9-1+F9,0) -> 0 | S9: =0.5*($O9*G9+$P9*H9+$Q9*I9+$R9*J9) -> 0 | T9: =0.5*($O9*K9+$P9*L9+$Q9*M9+$R9*N9) -> 0 | U9: =IF(A9="V",-2,0)+IF(A9="E",-1,0)+IF(A9="O",0,0)+IF(A9="L",1,0)+S9 -> -1 | V9: =IF(B9="V",-2,0)+IF(B9="E",-1,0)+IF(B9="O",0,0)+IF(B9="L",1,0)+T9 -> 1 | W9: =IF(A9="V",-2,0)+IF(A9="E",-1,0)+IF(A9="O",0,0)+IF(A9="L",1,0) -> -1 | X9: =IF(A9="V",-2,0)+IF(A9="E",-1,0)+IF(A9="O",0,0)+IF(A9="L",1,0)+S9 -> -1 | Y9: =IF(A9="V",-2,0)+IF(A9="E",-1,0)+IF(A9="O",0,0)+IF(A9="L",1,0)+S9*2 -> -1 | Z9: =IF(B9="V",-2,0)+IF(B9="E",-1,0)+IF(B9="O",0,0)+IF(B9="L",1,0) -> 1 | AA9: =IF(B9="V",-2,0)+IF(B9="E",-1,0)+IF(B9="O",0,0)+IF(B9="L",1,0)+T9 -> 1 | AB9: =IF(B9="V",-2,0)+IF(B9="E",-1,0)+IF(B9="O",0,0)+IF(B9="L",1,0)+T9*2 -> 1 | AC9: =(ABS(IF(W9<0,W9*Early,W9*Late))+ABS(IF(X9<0,X9*Early,X9*Late))+ABS(IF(Y9<0,Y9*Early,Y9*Late)))/3 -> 3 | AD9: =(ABS(IF(Z9<0,Z9*Early,Z9*Late))+ABS(IF(AA9<0,AA9*Early,AA9*Late))+ABS(IF(AB9<0,AB9*Early,AB9*Late)))/3 -> 4 | AE9: =S9*Delay+AC9 -> 3 | AF9: =T9*Delay+AD9 -> 4 | AG9: =A9&B9 -> EL | AH9: =AE9+AF9 -> 7
A10: O | B10: V | C10: =(IF($A10="V",1,0))+IF($B10="V",1,0) -> 1 | D10: =(IF($A10="E",1,0))+IF($B10="E",1,0) -> 0 | E10: =(IF($A10="O",1,0))+IF($B10="O",1,0) -> 1 | F10: =(IF($A10="L",1,0))+IF($B10="L",1,0) -> 0 | G10: =(IF(A10="V",1,0)) -> 0 | H10: =(IF(A10="E",1,0)) -> 0 | I10: =(IF(A10="O",1,0)) -> 1 | J10: =(IF(A10="L",1,0)) -> 0 | K10: =(IF(B10="V",1,0)) -> 1 | L10: =(IF(B10="E",1,0)) -> 0 | M10: =(IF(B10="O",1,0)) -> 0 | N10: =(IF(B10="L",1,0)) -> 0 | O10: =MAX(C10-1,0) -> 0 | P10: =MAX(O10-1+D10,0) -> 0 | Q10: =MAX(P10-1+E10,0) -> 0 | R10: =MAX(Q10-1+F10,0) -> 0 | S10: =0.5*($O10*G10+$P10*H10+$Q10*I10+$R10*J10) -> 0 | T10: =0.5*($O10*K10+$P10*L10+$Q10*M10+$R10*N10) -> 0 | U10: =IF(A10="V",-2,0)+IF(A10="E",-1,0)+IF(A10="O",0,0)+IF(A10="L",1,0)+S10 -> 0 | V10: =IF(B10="V",-2,0)+IF(B10="E",-1,0)+IF(B10="O",0,0)+IF(B10="L",1,0)+T10 -> -2 | W10: =IF(A10="V",-2,0)+IF(A10="E",-1,0)+IF(A10="O",0,0)+IF(A10="L",1,0) -> 0 | X10: =IF(A10="V",-2,0)+IF(A10="E",-1,0)+IF(A10="O",0,0)+IF(A10="L",1,0)+S10 -> 0 | Y10: =IF(A10="V",-2,0)+IF(A10="E",-1,0)+IF(A10="O",0,0)+IF(A10="L",1,0)+S10*2 -> 0 | Z10: =IF(B10="V",-2,0)+IF(B10="E",-1,0)+IF(B10="O",0,0)+IF(B10="L",1,0) -> -2 | AA10: =IF(B10="V",-2,0)+IF(B10="E",-1,0)+IF(B10="O",0,0)+IF(B10="L",1,0)+T10 -> -2 | AB10: =IF(B10="V",-2,0)+IF(B10="E",-1,0)+IF(B10="O",0,0)+IF(B10="L",1,0)+T10*2 -> -2 | AC10: =(ABS(IF(W10<0,W10*Early,W10*Late))+ABS(IF(X10<0,X10*Early,X10*Late))+ABS(IF(Y10<0,Y10*Early,Y10*Late)))/3 -> 0 | AD10: =(ABS(IF(Z10<0,Z10*Early,Z10*Late))+ABS(IF(AA10<0,AA10*Early,AA10*Late))+ABS(IF(AB10<0,AB10*Early,AB10*Late)))/3 -> 6 | AE10: =S10*Delay+AC10 -> 0 | AF10: =T10*Delay+AD10 -> 6 | AG10: =A10&B10 -> OV | AH10: =AE10+AF10 -> 6
A11: O | B11: E | C11: =(IF($A11="V",1,0))+IF($B11="V",1,0) -> 0 | D11: =(IF($A11="E",1,0))+IF($B11="E",1,0) -> 1 | E11: =(IF($A11="O",1,0))+IF($B11="O",1,0) -> 1 | F11: =(IF($A11="L",1,0))+IF($B11="L",1,0) -> 0 | G11: =(IF(A11="V",1,0)) -> 0 | H11: =(IF(A11="E",1,0)) -> 0 | I11: =(IF(A11="O",1,0)) -> 1 | J11: =(IF(A11="L",1,0)) -> 0 | K11: =(IF(B11="V",1,0)) -> 0 | L11: =(IF(B11="E",1,0)) -> 1 | M11: =(IF(B11="O",1,0)) -> 0 | N11: =(IF(B11="L",1,0)) -> 0 | O11: =MAX(C11-1,0) -> 0 | P11: =MAX(O11-1+D11,0) -> 0 | Q11: =MAX(P11-1+E11,0) -> 0 | R11: =MAX(Q11-1+F11,0) -> 0 | S11: =0.5*($O11*G11+$P11*H11+$Q11*I11+$R11*J11) -> 0 | T11: =0.5*($O11*K11+$P11*L11+$Q11*M11+$R11*N11) -> 0 | U11: =IF(A11="V",-2,0)+IF(A11="E",-1,0)+IF(A11="O",0,0)+IF(A11="L",1,0)+S11 -> 0 | V11: =IF(B11="V",-2,0)+IF(B11="E",-1,0)+IF(B11="O",0,0)+IF(B11="L",1,0)+T11 -> -1 | W11: =IF(A11="V",-2,0)+IF(A11="E",-1,0)+IF(A11="O",0,0)+IF(A11="L",1,0) -> 0 | X11: =IF(A11="V",-2,0)+IF(A11="E",-1,0)+IF(A11="O",0,0)+IF(A11="L",1,0)+S11 -> 0 | Y11: =IF(A11="V",-2,0)+IF(A11="E",-1,0)+IF(A11="O",0,0)+IF(A11="L",1,0)+S11*2 -> 0 | Z11: =IF(B11="V",-2,0)+IF(B11="E",-1,0)+IF(B11="O",0,0)+IF(B11="L",1,0) -> -1 | AA11: =IF(B11="V",-2,0)+IF(B11="E",-1,0)+IF(B11="O",0,0)+IF(B11="L",1,0)+T11 -> -1 | AB11: =IF(B11="V",-2,0)+IF(B11="E",-1,0)+IF(B11="O",0,0)+IF(B11="L",1,0)+T11*2 -> -1 | AC11: =(ABS(IF(W11<0,W11*Early,W11*Late))+ABS(IF(X11<0,X11*Early,X11*Late))+ABS(IF(Y11<0,Y11*Early,Y11*Late)))/3 -> 0 | AD11: =(ABS(IF(Z11<0,Z11*Early,Z11*Late))+ABS(IF(AA11<0,AA11*Early,AA11*Late))+ABS(IF(AB11<0,AB11*Early,AB11*Late)))/3 -> 3 | AE11: =S11*Delay+AC11 -> 0 | AF11: =T11*Delay+AD11 -> 3 | AG11: =A11&B11 -> OE | AH11: =AE11+AF11 -> 3
A12: O | B12: O | C12: =(IF($A12="V",1,0))+IF($B12="V",1,0) -> 0 | D12: =(IF($A12="E",1,0))+IF($B12="E",1,0) -> 0 | E12: =(IF($A12="O",1,0))+IF($B12="O",1,0) -> 2 | F12: =(IF($A12="L",1,0))+IF($B12="L",1,0) -> 0 | G12: =(IF(A12="V",1,0)) -> 0 | H12: =(IF(A12="E",1,0)) -> 0 | I12: =(IF(A12="O",1,0)) -> 1 | J12: =(IF(A12="L",1,0)) -> 0 | K12: =(IF(B12="V",1,0)) -> 0 | L12: =(IF(B12="E",1,0)) -> 0 | M12: =(IF(B12="O",1,0)) -> 1 | N12: =(IF(B12="L",1,0)) -> 0 | O12: =MAX(C12-1,0) -> 0 | P12: =MAX(O12-1+D12,0) -> 0 | Q12: =MAX(P12-1+E12,0) -> 1 | R12: =MAX(Q12-1+F12,0) -> 0 | S12: =0.5*($O12*G12+$P12*H12+$Q12*I12+$R12*J12) -> 0.5 | T12: =0.5*($O12*K12+$P12*L12+$Q12*M12+$R12*N12) -> 0.5 | U12: =IF(A12="V",-2,0)+IF(A12="E",-1,0)+IF(A12="O",0,0)+IF(A12="L",1,0)+S12 -> 0.5 | V12: =IF(B12="V",-2,0)+IF(B12="E",-1,0)+IF(B12="O",0,0)+IF(B12="L",1,0)+T12 -> 0.5 | W12: =IF(A12="V",-2,0)+IF(A12="E",-1,0)+IF(A12="O",0,0)+IF(A12="L",1,0) -> 0 | X12: =IF(A12="V",-2,0)+IF(A12="E",-1,0)+IF(A12="O",0,0)+IF(A12="L",1,0)+S12 -> 0.5 | Y12: =IF(A12="V",-2,0)+IF(A12="E",-1,0)+IF(A12="O",0,0)+IF(A12="L",1,0)+S12*2 -> 1 | Z12: =IF(B12="V",-2,0)+IF(B12="E",-1,0)+IF(B12="O",0,0)+IF(B12="L",1,0) -> 0 | AA12: =IF(B12="V",-2,0)+IF(B12="E",-1,0)+IF(B12="O",0,0)+IF(B12="L",1,0)+T12 -> 0.5 | AB12: =IF(B12="V",-2,0)+IF(B12="E",-1,0)+IF(B12="O",0,0)+IF(B12="L",1,0)+T12*2 -> 1 | AC12: =(ABS(IF(W12<0,W12*Early,W12*Late))+ABS(IF(X12<0,X12*Early,X12*Late))+ABS(IF(Y12<0,Y12*Early,Y12*Late)))/3 -> 2 | AD12: =(ABS(IF(Z12<0,Z12*Early,Z12*Late))+ABS(IF(AA12<0,AA12*Early,AA12*Late))+ABS(IF(AB12<0,AB12*Early,AB12*Late)))/3 -> 2 | AE12: =S12*Delay+AC12 -> 2.5 | AF12: =T12*Delay+AD12 -> 2.5 | AG12: =A12&B12 -> OO | AH12: =AE12+AF12 -> 5
A13: O | B13: L | C13: =(IF($A13="V",1,0))+IF($B13="V",1,0) -> 0 | D13: =(IF($A13="E",1,0))+IF($B13="E",1,0) -> 0 | E13: =(IF($A13="O",1,0))+IF($B13="O",1,0) -> 1 | F13: =(IF($A13="L",1,0))+IF($B13="L",1,0) -> 1 | G13: =(IF(A13="V",1,0)) -> 0 | H13: =(IF(A13="E",1,0)) -> 0 | I13: =(IF(A13="O",1,0)) -> 1 | J13: =(IF(A13="L",1,0)) -> 0 | K13: =(IF(B13="V",1,0)) -> 0 | L13: =(IF(B13="E",1,0)) -> 0 | M13: =(IF(B13="O",1,0)) -> 0 | N13: =(IF(B13="L",1,0)) -> 1 | O13: =MAX(C13-1,0) -> 0 | P13: =MAX(O13-1+D13,0) -> 0 | Q13: =MAX(P13-1+E13,0) -> 0 | R13: =MAX(Q13-1+F13,0) -> 0 | S13: =0.5*($O13*G13+$P13*H13+$Q13*I13+$R13*J13) -> 0 | T13: =0.5*($O13*K13+$P13*L13+$Q13*M13+$R13*N13) -> 0 | U13: =IF(A13="V",-2,0)+IF(A13="E",-1,0)+IF(A13="O",0,0)+IF(A13="L",1,0)+S13 -> 0 | V13: =IF(B13="V",-2,0)+IF(B13="E",-1,0)+IF(B13="O",0,0)+IF(B13="L",1,0)+T13 -> 1 | W13: =IF(A13="V",-2,0)+IF(A13="E",-1,0)+IF(A13="O",0,0)+IF(A13="L",1,0) -> 0 | X13: =IF(A13="V",-2,0)+IF(A13="E",-1,0)+IF(A13="O",0,0)+IF(A13="L",1,0)+S13 -> 0 | Y13: =IF(A13="V",-2,0)+IF(A13="E",-1,0)+IF(A13="O",0,0)+IF(A13="L",1,0)+S13*2 -> 0 | Z13: =IF(B13="V",-2,0)+IF(B13="E",-1,0)+IF(B13="O",0,0)+IF(B13="L",1,0) -> 1 | AA13: =IF(B13="V",-2,0)+IF(B13="E",-1,0)+IF(B13="O",0,0)+IF(B13="L",1,0)+T13 -> 1 | AB13: =IF(B13="V",-2,0)+IF(B13="E",-1,0)+IF(B13="O",0,0)+IF(B13="L",1,0)+T13*2 -> 1 | AC13: =(ABS(IF(W13<0,W13*Early,W13*Late))+ABS(IF(X13<0,X13*Early,X13*Late))+ABS(IF(Y13<0,Y13*Early,Y13*Late)))/3 -> 0 | AD13: =(ABS(IF(Z13<0,Z13*Early,Z13*Late))+ABS(IF(AA13<0,AA13*Early,AA13*Late))+ABS(IF(AB13<0,AB13*Early,AB13*Late)))/3 -> 4 | AE13: =S13*Delay+AC13 -> 0 | AF13: =T13*Delay+AD13 -> 4 | AG13: =A13&B13 -> OL | AH13: =AE13+AF13 -> 4
... A17: L | B17: L | C17: =(IF($A17="V",1,0))+IF($B17="V",1,0) -> 0 | D17: =(IF($A17="E",1,0))+IF($B17="E",1,0) -> 0 | E17: =(IF($A17="O",1,0))+IF($B17="O",1,0) -> 0 | F17: =(IF($A17="L",1,0))+IF($B17="L",1,0) -> 2 | G17: =(IF(A17="V",1,0)) -> 0 | H17: =(IF(A17="E",1,0)) -> 0 | I17: =(IF(A17="O",1,0)) -> 0 | J17: =(IF(A17="L",1,0)) -> 1 | K17: =(IF(B17="V",1,0)) -> 0 | L17: =(IF(B17="E",1,0)) -> 0 | M17: =(IF(B17="O",1,0)) -> 0 | N17: =(IF(B17="L",1,0)) -> 1 | O17: =MAX(C17-1,0) -> 0 | P17: =MAX(O17-1+D17,0) -> 0 | Q17: =MAX(P17-1+E17,0) -> 0 | R17: =MAX(Q17-1+F17,0) -> 1 | S17: =0.5*($O17*G17+$P17*H17+$Q17*I17+$R17*J17) -> 0.5 | T17: =0.5*($O17*K17+$P17*L17+$Q17*M17+$R17*N17) -> 0.5 | U17: =IF(A17="V",-2,0)+IF(A17="E",-1,0)+IF(A17="O",0,0)+IF(A17="L",1,0)+S17 -> 1.5 | V17: =IF(B17="V",-2,0)+IF(B17="E",-1,0)+IF(B17="O",0,0)+IF(B17="L",1,0)+T17 -> 1.5 | W17: =IF(A17="V",-2,0)+IF(A17="E",-1,0)+IF(A17="O",0,0)+IF(A17="L",1,0) -> 1 | X17: =IF(A17="V",-2,0)+IF(A17="E",-1,0)+IF(A17="O",0,0)+IF(A17="L",1,0)+S17 -> 1.5 | Y17: =IF(A17="V",-2,0)+IF(A17="E",-1,0)+IF(A17="O",0,0)+IF(A17="L",1,0)+S17*2 -> 2 | Z17: =IF(B17="V",-2,0)+IF(B17="E",-1,0)+IF(B17="O",0,0)+IF(B17="L",1,0) -> 1 | AA17: =IF(B17="V",-2,0)+IF(B17="E",-1,0)+IF(B17="O",0,0)+IF(B17="L",1,0)+T17 -> 1.5 | AB17: =IF(B17="V",-2,0)+IF(B17="E",-1,0)+IF(B17="O",0,0)+IF(B17="L",1,0)+T17*2 -> 2 | AC17: =(ABS(IF(W17<0,W17*Early,W17*Late))+ABS(IF(X17<0,X17*Early,X17*Late))+ABS(IF(Y17<0,Y17*Early,Y17*Late)))/3 -> 6 | AD17: =(ABS(IF(Z17<0,Z17*Early,Z17*Late))+ABS(IF(AA17<0,AA17*Early,AA17*Late))+ABS(IF(AB17<0,AB17*Early,AB17*Late)))/3 -> 6 | AE17: =S17*Delay+AC17 -> 6.5 | AF17: =T17*Delay+AD17 -> 6.5 | AG17: =A17&B17 -> LL | AH17: =AE17+AF17 -> 13

Sheet Master
A1: Game ID | B1: Vehicle A | C1: Vehicle B | D1: Vehicle C | E1: V | F1: E | G1: O | H1: L | I1: AV | J1: AE | K1: AO | L1: AL | M1: BV | N1: BE | O1: BO | P1: BL | Q1: CV | R1: CE | S1: CO | T1: CL | U1: QLV | V1: QLE | W1: QLO | X1: QLL | Y1: E(Delay A) | Z1: E(Delay B) | AA1: E(Delay C) | AB1: E(ArrivalTimeA) | AC1: E(ArrivalTimeB) | AD1: E(ArrivalTimeC) | AE1: ArrA1 | AF1: ArrA2 | AG1: ArrA3 | AH1: ArrB1 | AI1: ArrB2 | AJ1: ArrB3 | AK1: ArrC1 | AL1: ArrC2 | AM1: ArrC3 | AN1: E(SD A) | AO1: E(SD B) | AP1: E(SD C) | AQ1: Price A | AR1: Price B | AS1: Price C | AT1: Nash A | AU1: Nash B | AV1: Nash C | AW1: Equilibrium | AX1: ARRIVAL | AY1: TC | AZ1: No(A) | BA1: No(B) | BB1: NO© | BC1: 2-Player(NoA) | BD1: 2-Player(NoB) | BE1: 2-Player(NoC) | BF1: MC(A) | BG1: MC(B) | BH1: MC© | BI1: =AX1 -> ARRIVAL | BJ1: Nash A | BK1: Nash B | BL1: Nash C | BM1: Equilibrium
A2: 1 | B2: V | C2: V | D2: V | E2: =(IF($B2="V",1,0))+IF($C2="V",1,0)+IF($D2="V",1,0) -> 3 | F2: =(IF($B2="E",1,0))+IF($C2="E",1,0)+IF($D2="E",1,0) -> 0 | G2: =(IF($B2="O",1,0))+IF($C2="O",1,0)+IF($D2="O",1,0) -> 0 | H2: =(IF($B2="L",1,0))+IF($C2="L",1,0)+IF($D2="L",1,0) -> 0 | I2: =(IF(B2="V",1,0)) -> 1 | J2: =(IF(B2="E",1,0)) -> 0 | K2: =(IF(B2="O",1,0)) -> 0 | L2: =(IF(B2="L",1,0)) -> 0 | M2: =(IF(C2="V",1,0)) -> 1 | N2: =(IF(C2="E",1,0)) -> 0 | O2: =(IF(C2="O",1,0)) -> 0 | P2: =(IF(C2="L",1,0)) -> 0 | Q2: =(IF(D2="V",1,0)) -> 1 | R2: =(IF(D2="E",1,0)) -> 0 | S2: =(IF(D2="O",1,0)) -> 0 | T2: =(IF(D2="L",1,0)) -> 0 | U2: =MAX(E2-1,0) -> 2 | V2: =MAX(U2-1+F2,0) -> 1 | W2: =MAX(V2-1+G2,0) -> 0 | X2: =MAX(W2-1+H2,0) -> 0 | Y2: =0.5*(E2*I2+F2*J2+G2*K2+H2*L2-1)+(0+$U2*J2+$V2*K2+$W2*L2) -> 1 | Z2: =0.5*(E2*M2+F2*N2+G2*O2+H2*P2-1)+(0+$U2*N2+$V2*O2+$W2*P2) -> 1 | AA2: =0.5*(E2*Q2+F2*R2+G2*S2+H2*T2-1)+(0+$U2*R2+$V2*S2+$W2*T2) -> 1 | AB2: =IF(B2="V",-2,0)+IF(B2="E",-1,0)+IF(B2="O",0,0)+IF(B2="L",1,0)+Y2 -> -1 | AC2: =IF(C2="V",-2,0)+IF(C2="E",-1,0)+IF(C2="O",0,0)+IF(C2="L",1,0)+Z2 -> -1 | AD2: =IF(D2="V",-2,0)+IF(D2="E",-1,0)+IF(D2="O",0,0)+IF(D2="L",1,0)+AA2 -> -1 | AE2: =IF(B2="V",-2,0)+IF(B2="E",-1,0)+IF(B2="O",0,0)+IF(B2="L",1,0) -> -2 | AF2: =IF(B2="V",-2,0)+IF(B2="E",-1,0)+IF(B2="O",0,0)+IF(B2="L",1,0)+Y2 -> -1 | AG2: =IF(B2="V",-2,0)+IF(B2="E",-1,0)+IF(B2="O",0,0)+IF(B2="L",1,0)+Y2*2 -> 0 | AH2: =IF(C2="V",-2,0)+IF(C2="E",-1,0)+IF(C2="O",0,0)+IF(C2="L",1,0) -> -2 | AI2: =IF(C2="V",-2,0)+IF(C2="E",-1,0)+IF(C2="O",0,0)+IF(C2="L",1,0)+Z2 -> -1 | AJ2: =IF(C2="V",-2,0)+IF(C2="E",-1,0)+IF(C2="O",0,0)+IF(C2="L",1,0)+Z2*2 -> 0 | AK2: =IF(D2="V",-2,0)+IF(D2="E",-1,0)+IF(D2="O",0,0)+IF(D2="L",1,0) -> -2 | AL2: =IF(D2="V",-2,0)+IF(D2="E",-1,0)+IF(D2="O",0,0)+IF(D2="L",1,0)+AA2 -> -1 | AM2: =IF(D2="V",-2,0)+IF(D2="E",-1,0)+IF(D2="O",0,0)+IF(D2="L",1,0)+AA2*2 -> 0 | AN2: =(ABS(IF(AE2<0,AE2*Early,AE2*Late))+ABS(IF(AF2<0,AF2*Early,AF2*Late))+ABS(IF(AG2<0,AG2*Early,AG2*Late)))/3 -> 3 | AO2: =(ABS(IF(AH2<0,AH2*Early,AH2*Late))+ABS(IF(AI2<0,AI2*Early,AI2*Late))+ABS(IF(AJ2<0,AJ2*Early,AJ2*Late)))/3 -> 3 | AP2: =(ABS(IF(AK2<0,AK2*Early,AK2*Late))+ABS(IF(AL2<0,AL2*Early,AL2*Late))+ABS(IF(AM2<0,AM2*Early,AM2*Late)))/3 -> 3 | AQ2: =Y2*Delay+AN2 -> 4 | AR2: =Z2*Delay+AO2 -> 4 | AS2: =AA2*Delay+AP2 -> 4 | AT2: =VLOOKUP(A2,SortA!$A$1:$AT$65,46,FALSE()) -> 0 | AU2: =VLOOKUP(A2,SortB!$A$1:$AT$65,46,FALSE()) -> 0 | AV2: =VLOOKUP(A2,SortC!$A$1:$AT$65,46,FALSE()) -> 0 | AW2: =IF(SUM(AT2:AV2)=3,1,0) -> 0 | AX2: =B2&C2&D2 -> VVV | AY2: =AQ2+AR2+AS2 -> 12 | AZ2: =RIGHT(AX2,2) -> VV | BA2: =LEFT(AX2,1)&RIGHT(AX2,1) -> VV | BB2: =LEFT(AX2,2) -> VV | BC2: =VLOOKUP(AZ2,TwoPlayers!$AG$1:$AH$17,2,FALSE()) -> 10 | BD2: =VLOOKUP(BA2,TwoPlayers!$AG$1:$AH$17,2,FALSE()) -> 10 | BE2: =VLOOKUP(BB2,TwoPlayers!$AG$1:$AH$17,2,FALSE()) -> 10 | BF2: =$AY2-BC2 -> 2 | BG2: =$AY2-BD2 -> 2 | BH2: =$AY2-BE2 -> 2 | BI2: =AX2 -> VVV | BJ2: =VLOOKUP(A2,SortA!$A$1:$BM$65,65,FALSE()) -> 0 | BK2: =VLOOKUP(A2,SortB!$A$1:$BM$65,65,FALSE()) -> 0 | BL2: =VLOOKUP(A2,SortC!$A$1:$BM$65,65,FALSE()) -> 0 | BM2: =IF(SUM(BJ2:BL2)=3,1,0) -> 0
A3: =A2+1 -> 2 | B3: V | C3: V | D3: E | E3: =(IF($B3="V",1,0))+IF($C3="V",1,0)+IF($D3="V",1,0) -> 2 | F3: =(IF($B3="E",1,0))+IF($C3="E",1,0)+IF($D3="E",1,0) -> 1 | G3: =(IF($B3="O",1,0))+IF($C3="O",1,0)+IF($D3="O",1,0) -> 0 | H3: =(IF($B3="L",1,0))+IF($C3="L",1,0)+IF($D3="L",1,0) -> 0 | I3: =(IF(B3="V",1,0)) -> 1 | J3: =(IF(B3="E",1,0)) -> 0 | K3: =(IF(B3="O",1,0)) -> 0 | L3: =(IF(B3="L",1,0)) -> 0 | M3: =(IF(C3="V",1,0)) -> 1 | N3: =(IF(C3="E",1,0)) -> 0 | O3: =(IF(C3="O",1,0)) -> 0 | P3: =(IF(C3="L",1,0)) -> 0 | Q3: =(IF(D3="V",1,0)) -> 0 | R3: =(IF(D3="E",1,0)) -> 1 | S3: =(IF(D3="O",1,0)) -> 0 | T3: =(IF(D3="L",1,0)) -> 0 | U3: =MAX(E3-1,0) -> 1 | V3: =MAX(U3-1+F3,0) -> 1 | W3: =MAX(V3-1+G3,0) -> 0 | X3: =MAX(W3-1+H3,0) -> 0 | Y3: =0.5*(E3*I3+F3*J3+G3*K3+H3*L3-1)+(0+$U3*J3+$V3*K3+$W3*L3) -> 0.5 | Z3: =0.5*(E3*M3+F3*N3+G3*O3+H3*P3-1)+(0+$U3*N3+$V3*O3+$W3*P3) -> 0.5 | AA3: =0.5*(E3*Q3+F3*R3+G3*S3+H3*T3-1)+(0+$U3*R3+$V3*S3+$W3*T3) -> 1 | AB3: =IF(B3="V",-2,0)+IF(B3="E",-1,0)+IF(B3="O",0,0)+IF(B3="L",1,0)+Y3 -> -1.5 | AC3: =IF(C3="V",-2,0)+IF(C3="E",-1,0)+IF(C3="O",0,0)+IF(C3="L",1,0)+Z3 -> -1.5 | AD3: =IF(D3="V",-2,0)+IF(D3="E",-1,0)+IF(D3="O",0,0)+IF(D3="L",1,0)+AA3 -> 0 | AE3: =IF(B3="V",-2,0)+IF(B3="E",-1,0)+IF(B3="O",0,0)+IF(B3="L",1,0) -> -2 | AF3: =IF(B3="V",-2,0)+IF(B3="E",-1,0)+IF(B3="O",0,0)+IF(B3="L",1,0)+Y3 -> -1.5 | AG3: =IF(B3="V",-2,0)+IF(B3="E",-1,0)+IF(B3="O",0,0)+IF(B3="L",1,0)+Y3*2 -> -1 | AH3: =IF(C3="V",-2,0)+IF(C3="E",-1,0)+IF(C3="O",0,0)+IF(C3="L",1,0) -> -2 | AI3: =IF(C3="V",-2,0)+IF(C3="E",-1,0)+IF(C3="O",0,0)+IF(C3="L",1,0)+Z3 -> -1.5 | AJ3: =IF(C3="V",-2,0)+IF(C3="E",-1,0)+IF(C3="O",0,0)+IF(C3="L",1,0)+Z3*2 -> -1 | AK3: =IF(D3="V",-2,0)+IF(D3="E",-1,0)+IF(D3="O",0,0)+IF(D3="L",1,0) -> -1 | AL3: =IF(D3="V",-2,0)+IF(D3="E",-1,0)+IF(D3="O",0,0)+IF(D3="L",1,0)+AA3 -> 0 | AM3: =IF(D3="V",-2,0)+IF(D3="E",-1,0)+IF(D3="O",0,0)+IF(D3="L",1,0)+AA3*2 -> 1 | AN3: =(ABS(IF(AE3<0,AE3*Early,AE3*Late))+ABS(IF(AF3<0,AF3*Early,AF3*Late))+ABS(IF(AG3<0,AG3*Early,AG3*Late)))/3 -> 4.5 | AO3: =(ABS(IF(AH3<0,AH3*Early,AH3*Late))+ABS(IF(AI3<0,AI3*Early,AI3*Late))+ABS(IF(AJ3<0,AJ3*Early,AJ3*Late)))/3 -> 4.5 | AP3: =(ABS(IF(AK3<0,AK3*Early,AK3*Late))+ABS(IF(AL3<0,AL3*Early,AL3*Late))+ABS(IF(AM3<0,AM3*Early,AM3*Late)))/3 -> 2.3333333 | AQ3: =Y3*Delay+AN3 -> 5 | AR3: =Z3*Delay+AO3 -> 5 | AS3: =AA3*Delay+AP3 -> 3.3333333 | AT3: =VLOOKUP(A3,SortA!$A$1:$AT$65,46,FALSE()) -> 0 | AU3: =VLOOKUP(A3,SortB!$A$1:$AT$65,46,FALSE()) -> 0 | AV3: =VLOOKUP(A3,SortC!$A$1:$AT$65,46,FALSE()) -> 0 | AW3: =IF(SUM(AT3:AV3)=3,1,0) -> 0 | AX3: =B3&C3&D3 -> VVE | AY3: =AQ3+AR3+AS3 -> 13.333333 | AZ3: =RIGHT(AX3,2) -> VE | BA3: =LEFT(AX3,1)&RIGHT(AX3,1) -> VE | BB3: =LEFT(AX3,2) -> VV | BC3: =VLOOKUP(AZ3,TwoPlayers!$AG$1:$AH$17,2,FALSE()) -> 9 | BD3: =VLOOKUP(BA3,TwoPlayers!$AG$1:$AH$17,2,FALSE()) -> 9 | BE3: =VLOOKUP(BB3,TwoPlayers!$AG$1:$AH$17,2,FALSE()) -> 10 | BF3: =$AY3-BC3 -> 4.3333333 | BG3: =$AY3-BD3 -> 4.3333333 | BH3: =$AY3-BE3 -> 3.3333333 | BI3: =AX3 -> VVE | BJ3: =VLOOKUP(A3,SortA!$A$1:$BM$65,65,FALSE()) -> 0 | BK3: =VLOOKUP(A3,SortB!$A$1:$BM$65,65,FALSE()) -> 0 | BL3: =VLOOKUP(A3,SortC!$A$1:$BM$65,65,FALSE()) -> 0 | BM3: =IF(SUM(BJ3:BL3)=3,1,0) -> 0
A4: =A3+1 -> 3 | B4: V | C4: V | D4: O | E4: =(IF($B4="V",1,0))+IF($C4="V",1,0)+IF($D4="V",1,0) -> 2 | F4: =(IF($B4="E",1,0))+IF($C4="E",1,0)+IF($D4="E",1,0) -> 0 | G4: =(IF($B4="O",1,0))+IF($C4="O",1,0)+IF($D4="O",1,0) -> 1 | H4: =(IF($B4="L",1,0))+IF($C4="L",1,0)+IF($D4="L",1,0) -> 0 | I4: =(IF(B4="V",1,0)) -> 1 | J4: =(IF(B4="E",1,0)) -> 0 | K4: =(IF(B4="O",1,0)) -> 0 | L4: =(IF(B4="L",1,0)) -> 0 | M4: =(IF(C4="V",1,0)) -> 1 | N4: =(IF(C4="E",1,0)) -> 0 | O4: =(IF(C4="O",1,0)) -> 0 | P4: =(IF(C4="L",1,0)) -> 0 | Q4: =(IF(D4="V",1,0)) -> 0 | R4: =(IF(D4="E",1,0)) -> 0 | S4: =(IF(D4="O",1,0)) -> 1 | T4: =(IF(D4="L",1,0)) -> 0 | U4: =MAX(E4-1,0) -> 1 | V4: =MAX(U4-1+F4,0) -> 0 | W4: =MAX(V4-1+G4,0) -> 0 | X4: =MAX(W4-1+H4,0) -> 0 | Y4: =0.5*(E4*I4+F4*J4+G4*K4+H4*L4-1)+(0+$U4*J4+$V4*K4+$W4*L4) -> 0.5 | Z4: =0.5*(E4*M4+F4*N4+G4*O4+H4*P4-1)+(0+$U4*N4+$V4*O4+$W4*P4) -> 0.5 | AA4: =0.5*(E4*Q4+F4*R4+G4*S4+H4*T4-1)+(0+$U4*R4+$V4*S4+$W4*T4) -> 0 | AB4: =IF(B4="V",-2,0)+IF(B4="E",-1,0)+IF(B4="O",0,0)+IF(B4="L",1,0)+Y4 -> -1.5 | AC4: =IF(C4="V",-2,0)+IF(C4="E",-1,0)+IF(C4="O",0,0)+IF(C4="L",1,0)+Z4 -> -1.5 | AD4: =IF(D4="V",-2,0)+IF(D4="E",-1,0)+IF(D4="O",0,0)+IF(D4="L",1,0)+AA4 -> 0 | AE4: =IF(B4="V",-2,0)+IF(B4="E",-1,0)+IF(B4="O",0,0)+IF(B4="L",1,0) -> -2 | AF4: =IF(B4="V",-2,0)+IF(B4="E",-1,0)+IF(B4="O",0,0)+IF(B4="L",1,0)+Y4 -> -1.5 | AG4: =IF(B4="V",-2,0)+IF(B4="E",-1,0)+IF(B4="O",0,0)+IF(B4="L",1,0)+Y4*2 -> -1 | AH4: =IF(C4="V",-2,0)+IF(C4="E",-1,0)+IF(C4="O",0,0)+IF(C4="L",1,0) -> -2 | AI4: =IF(C4="V",-2,0)+IF(C4="E",-1,0)+IF(C4="O",0,0)+IF(C4="L",1,0)+Z4 -> -1.5 | AJ4: =IF(C4="V",-2,0)+IF(C4="E",-1,0)+IF(C4="O",0,0)+IF(C4="L",1,0)+Z4*2 -> -1 | AK4: =IF(D4="V",-2,0)+IF(D4="E",-1,0)+IF(D4="O",0,0)+IF(D4="L",1,0) -> 0 | AL4: =IF(D4="V",-2,0)+IF(D4="E",-1,0)+IF(D4="O",0,0)+IF(D4="L",1,0)+AA4 -> 0 | AM4: =IF(D4="V",-2,0)+IF(D4="E",-1,0)+IF(D4="O",0,0)+IF(D4="L",1,0)+AA4*2 -> 0 | AN4: =(ABS(IF(AE4<0,AE4*Early,AE4*Late))+ABS(IF(AF4<0,AF4*Early,AF4*Late))+ABS(IF(AG4<0,AG4*Early,AG4*Late)))/3 -> 4.5 | AO4: =(ABS(IF(AH4<0,AH4*Early,AH4*Late))+ABS(IF(AI4<0,AI4*Early,AI4*Late))+ABS(IF(AJ4<0,AJ4*Early,AJ4*Late)))/3 -> 4.5 | AP4: =(ABS(IF(AK4<0,AK4*Early,AK4*Late))+ABS(IF(AL4<0,AL4*Early,AL4*Late))+ABS(IF(AM4<0,AM4*Early,AM4*Late)))/3 -> 0 | AQ4: =Y4*Delay+AN4 -> 5 | AR4: =Z4*Delay+AO4 -> 5 | AS4: =AA4*Delay+AP4 -> 0 | AT4: =VLOOKUP(A4,SortA!$A$1:$AT$65,46,FALSE()) -> 0 | AU4: =VLOOKUP(A4,SortB!$A$1:$AT$65,46,FALSE()) -> 0 | AV4: =VLOOKUP(A4,SortC!$A$1:$AT$65,46,FALSE()) -> 1 | AW4: =IF(SUM(AT4:AV4)=3,1,0) -> 0 | AX4: =B4&C4&D4 -> VVO | AY4: =AQ4+AR4+AS4 -> 10 | AZ4: =RIGHT(AX4,2) -> VO | BA4: =LEFT(AX4,1)&RIGHT(AX4,1) -> VO | BB4: =LEFT(AX4,2) -> VV | BC4: =VLOOKUP(AZ4,TwoPlayers!$AG$1:$AH$17,2,FALSE()) -> 6 | BD4: =VLOOKUP(BA4,TwoPlayers!$AG$1:$AH$17,2,FALSE()) -> 6 | BE4: =VLOOKUP(BB4,TwoPlayers!$AG$1:$AH$17,2,FALSE()) -> 10 | BF4: =$AY4-BC4 -> 4 | BG4: =$AY4-BD4 -> 4 | BH4: =$AY4-BE4 -> 0 | BI4: =AX4 -> VVO | BJ4: =VLOOKUP(A4,SortA!$A$1:$BM$65,65,FALSE()) -> 0 | BK4: =VLOOKUP(A4,SortB!$A$1:$BM$65,65,FALSE()) -> 0 | BL4: =VLOOKUP(A4,SortC!$A$1:$BM$65,65,FALSE()) -> 1 | BM4: =IF(SUM(BJ4:BL4)=3,1,0) -> 0
A5: =A4+1 -> 4 | B5: V | C5: V | D5: L | E5: =(IF($B5="V",1,0))+IF($C5="V",1,0)+IF($D5="V",1,0) -> 2 | F5: =(IF($B5="E",1,0))+IF($C5="E",1,0)+IF($D5="E",1,0) -> 0 | G5: =(IF($B5="O",1,0))+IF($C5="O",1,0)+IF($D5="O",1,0) -> 0 | H5: =(IF($B5="L",1,0))+IF($C5="L",1,0)+IF($D5="L",1,0) -> 1 | I5: =(IF(B5="V",1,0)) -> 1 | J5: =(IF(B5="E",1,0)) -> 0 | K5: =(IF(B5="O",1,0)) -> 0 | L5: =(IF(B5="L",1,0)) -> 0 | M5: =(IF(C5="V",1,0)) -> 1 | N5: =(IF(C5="E",1,0)) -> 0 | O5: =(IF(C5="O",1,0)) -> 0 | P5: =(IF(C5="L",1,0)) -> 0 | Q5: =(IF(D5="V",1,0)) -> 0 | R5: =(IF(D5="E",1,0)) -> 0 | S5: =(IF(D5="O",1,0)) -> 0 | T5: =(IF(D5="L",1,0)) -> 1 | U5: =MAX(E5-1,0) -> 1 | V5: =MAX(U5-1+F5,0) -> 0 | W5: =MAX(V5-1+G5,0) -> 0 | X5: =MAX(W5-1+H5,0) -> 0 | Y5: =0.5*(E5*I5+F5*J5+G5*K5+H5*L5-1)+(0+$U5*J5+$V5*K5+$W5*L5) -> 0.5 | Z5: =0.5*(E5*M5+F5*N5+G5*O5+H5*P5-1)+(0+$U5*N5+$V5*O5+$W5*P5) -> 0.5 | AA5: =0.5*(E5*Q5+F5*R5+G5*S5+H5*T5-1)+(0+$U5*R5+$V5*S5+$W5*T5) -> 0 | AB5: =IF(B5="V",-2,0)+IF(B5="E",-1,0)+IF(B5="O",0,0)+IF(B5="L",1,0)+Y5 -> -1.5 | AC5: =IF(C5="V",-2,0)+IF(C5="E",-1,0)+IF(C5="O",0,0)+IF(C5="L",1,0)+Z5 -> -1.5 | AD5: =IF(D5="V",-2,0)+IF(D5="E",-1,0)+IF(D5="O",0,0)+IF(D5="L",1,0)+AA5 -> 1 | AE5: =IF(B5="V",-2,0)+IF(B5="E",-1,0)+IF(B5="O",0,0)+IF(B5="L",1,0) -> -2 | AF5: =IF(B5="V",-2,0)+IF(B5="E",-1,0)+IF(B5="O",0,0)+IF(B5="L",1,0)+Y5 -> -1.5 | AG5: =IF(B5="V",-2,0)+IF(B5="E",-1,0)+IF(B5="O",0,0)+IF(B5="L",1,0)+Y5*2 -> -1 | AH5: =IF(C5="V",-2,0)+IF(C5="E",-1,0)+IF(C5="O",0,0)+IF(C5="L",1,0) -> -2 | AI5: =IF(C5="V",-2,0)+IF(C5="E",-1,0)+IF(C5="O",0,0)+IF(C5="L",1,0)+Z5 -> -1.5 | AJ5: =IF(C5="V",-2,0)+IF(C5="E",-1,0)+IF(C5="O",0,0)+IF(C5="L",1,0)+Z5*2 -> -1 | AK5: =IF(D5="V",-2,0)+IF(D5="E",-1,0)+IF(D5="O",0,0)+IF(D5="L",1,0) -> 1 | AL5: =IF(D5="V",-2,0)+IF(D5="E",-1,0)+IF(D5="O",0,0)+IF(D5="L",1,0)+AA5 -> 1 | AM5: =IF(D5="V",-2,0)+IF(D5="E",-1,0)+IF(D5="O",0,0)+IF(D5="L",1,0)+AA5*2 -> 1 | AN5: =(ABS(IF(AE5<0,AE5*Early,AE5*Late))+ABS(IF(AF5<0,AF5*Early,AF5*Late))+ABS(IF(AG5<0,AG5*Early,AG5*Late)))/3 -> 4.5 | AO5: =(ABS(IF(AH5<0,AH5*Early,AH5*Late))+ABS(IF(AI5<0,AI5*Early,AI5*Late))+ABS(IF(AJ5<0,AJ5*Early,AJ5*Late)))/3 -> 4.5 | AP5: =(ABS(IF(AK5<0,AK5*Early,AK5*Late))+ABS(IF(AL5<0,AL5*Early,AL5*Late))+ABS(IF(AM5<0,AM5*Early,AM5*Late)))/3 -> 4 | AQ5: =Y5*Delay+AN5 -> 5 | AR5: =Z5*Delay+AO5 -> 5 | AS5: =AA5*Delay+AP5 -> 4 | AT5: =VLOOKUP(A5,SortA!$A$1:$AT$65,46,FALSE()) -> 0 | AU5: =VLOOKUP(A5,SortB!$A$1:$AT$65,46,FALSE()) -> 0 | AV5: =VLOOKUP(A5,SortC!$A$1:$AT$65,46,FALSE()) -> 0 | AW5: =IF(SUM(AT5:AV5)=3,1,0) -> 0 | AX5: =B5&C5&D5 -> VVL | AY5: =AQ5+AR5+AS5 -> 14 | AZ5: =RIGHT(AX5,2) -> VL | BA5: =LEFT(AX5,1)&RIGHT(AX5,1) -> VL | BB5: =LEFT(AX5,2) -> VV | BC5: =VLOOKUP(AZ5,TwoPlayers!$AG$1:$AH$17,2,FALSE()) -> 10 | BD5: =VLOOKUP(BA5,TwoPlayers!$AG$1:$AH$17,2,FALSE()) -> 10 | BE5: =VLOOKUP(BB5,TwoPlayers!$AG$1:$AH$17,2,FALSE()) -> 10 | BF5: =$AY5-BC5 -> 4 | BG5: =$AY5-BD5 -> 4 | BH5: =$AY5-BE5 -> 4 | BI5: =AX5 -> VVL | BJ5: =VLOOKUP(A5,SortA!$A$1:$BM$65,65,FALSE()) -> 0 | BK5: =VLOOKUP(A5,SortB!$A$1:$BM$65,65,FALSE()) -> 0 | BL5: =VLOOKUP(A5,SortC!$A$1:$BM$65,65,FALSE()) -> 0 | BM5: =IF(SUM(BJ5:BL5)=3,1,0) -> 0
A6: =A5+1 -> 5 | B6: V | C6: E | D6: V | E6: =(IF($B6="V",1,0))+IF($C6="V",1,0)+IF($D6="V",1,0) -> 2 | F6: =(IF($B6="E",1,0))+IF($C6="E",1,0)+IF($D6="E",1,0) -> 1 | G6: =(IF($B6="O",1,0))+IF($C6="O",1,0)+IF($D6="O",1,0) -> 0 | H6: =(IF($B6="L",1,0))+IF($C6="L",1,0)+IF($D6="L",1,0) -> 0 | I6: =(IF(B6="V",1,0)) -> 1 | J6: =(IF(B6="E",1,0)) -> 0 | K6: =(IF(B6="O",1,0)) -> 0 | L6: =(IF(B6="L",1,0)) -> 0 | M6: =(IF(C6="V",1,0)) -> 0 | N6: =(IF(C6="E",1,0)) -> 1 | O6: =(IF(C6="O",1,0)) -> 0 | P6: =(IF(C6="L",1,0)) -> 0 | Q6: =(IF(D6="V",1,0)) -> 1 | R6: =(IF(D6="E",1,0)) -> 0 | S6: =(IF(D6="O",1,0)) -> 0 | T6: =(IF(D6="L",1,0)) -> 0 | U6: =MAX(E6-1,0) -> 1 | V6: =MAX(U6-1+F6,0) -> 1 | W6: =MAX(V6-1+G6,0) -> 0 | X6: =MAX(W6-1+H6,0) -> 0 | Y6: =0.5*(E6*I6+F6*J6+G6*K6+H6*L6-1)+(0+$U6*J6+$V6*K6+$W6*L6) -> 0.5 | Z6: =0.5*(E6*M6+F6*N6+G6*O6+H6*P6-1)+(0+$U6*N6+$V6*O6+$W6*P6) -> 1 | AA6: =0.5*(E6*Q6+F6*R6+G6*S6+H6*T6-1)+(0+$U6*R6+$V6*S6+$W6*T6) -> 0.5 | AB6: =IF(B6="V",-2,0)+IF(B6="E",-1,0)+IF(B6="O",0,0)+IF(B6="L",1,0)+Y6 -> -1.5 | AC6: =IF(C6="V",-2,0)+IF(C6="E",-1,0)+IF(C6="O",0,0)+IF(C6="L",1,0)+Z6 -> 0 | AD6: =IF(D6="V",-2,0)+IF(D6="E",-1,0)+IF(D6="O",0,0)+IF(D6="L",1,0)+AA6 -> -1.5 | AE6: =IF(B6="V",-2,0)+IF(B6="E",-1,0)+IF(B6="O",0,0)+IF(B6="L",1,0) -> -2 | AF6: =IF(B6="V",-2,0)+IF(B6="E",-1,0)+IF(B6="O",0,0)+IF(B6="L",1,0)+Y6 -> -1.5 | AG6: =IF(B6="V",-2,0)+IF(B6="E",-1,0)+IF(B6="O",0,0)+IF(B6="L",1,0)+Y6*2 -> -1 | AH6: =IF(C6="V",-2,0)+IF(C6="E",-1,0)+IF(C6="O",0,0)+IF(C6="L",1,0) -> -1 | AI6: =IF(C6="V",-2,0)+IF(C6="E",-1,0)+IF(C6="O",0,0)+IF(C6="L",1,0)+Z6 -> 0 | AJ6: =IF(C6="V",-2,0)+IF(C6="E",-1,0)+IF(C6="O",0,0)+IF(C6="L",1,0)+Z6*2 -> 1 | AK6: =IF(D6="V",-2,0)+IF(D6="E",-1,0)+IF(D6="O",0,0)+IF(D6="L",1,0) -> -2 | AL6: =IF(D6="V",-2,0)+IF(D6="E",-1,0)+IF(D6="O",0,0)+IF(D6="L",1,0)+AA6 -> -1.5 | AM6: =IF(D6="V",-2,0)+IF(D6="E",-1,0)+IF(D6="O",0,0)+IF(D6="L",1,0)+AA6*2 -> -1 | AN6: =(ABS(IF(AE6<0,AE6*Early,AE6*Late))+ABS(IF(AF6<0,AF6*Early,AF6*Late))+ABS(IF(AG6<0,AG6*Early,AG6*Late)))/3 -> 4.5 | AO6: =(ABS(IF(AH6<0,AH6*Early,AH6*Late))+ABS(IF(AI6<0,AI6*Early,AI6*Late))+ABS(IF(AJ6<0,AJ6*Early,AJ6*Late)))/3 -> 2.3333333 | AP6: =(ABS(IF(AK6<0,AK6*Early,AK6*Late))+ABS(IF(AL6<0,AL6*Early,AL6*Late))+ABS(IF(AM6<0,AM6*Early,AM6*Late)))/3 -> 4.5 | AQ6: =Y6*Delay+AN6 -> 5 | AR6: =Z6*Delay+AO6 -> 3.3333333 | AS6: =AA6*Delay+AP6 -> 5 | AT6: =VLOOKUP(A6,SortA!$A$1:$AT$65,46,FALSE()) -> 0 | AU6: =VLOOKUP(A6,SortB!$A$1:$AT$65,46,FALSE()) -> 0 | AV6: =VLOOKUP(A6,SortC!$A$1:$AT$65,46,FALSE()) -> 0 | AW6: =IF(SUM(AT6:AV6)=3,1,0) -> 0 | AX6: =B6&C6&D6 -> VEV | AY6: =AQ6+AR6+AS6 -> 13.333333 | AZ6: =RIGHT(AX6,2) -> EV | BA6: =LEFT(AX6,1)&RIGHT(AX6,1) -> VV | BB6: =LEFT(AX6,2) -> VE | BC6: =VLOOKUP(AZ6,TwoPlayers!$AG$1:$AH$17,2,FALSE()) -> 9 | BD6: =VLOOKUP(BA6,TwoPlayers!$AG$1:$AH$17,2,FALSE()) -> 10 | BE6: =VLOOKUP(BB6,TwoPlayers!$AG$1:$AH$17,2,FALSE()) -> 9 | BF6: =$AY6-BC6 -> 4.3333333 | BG6: =$AY6-BD6 -> 3.3333333 | BH6: =$AY6-BE6 -> 4.3333333 | BI6: =AX6 -> VEV | BJ6: =VLOOKUP(A6,SortA!$A$1:$BM$65,65,FALSE()) -> 0 | BK6: =VLOOKUP(A6,SortB!$A$1:$BM$65,65,FALSE()) -> 0 | BL6: =VLOOKUP(A6,SortC!$A$1:$BM$65,65,FALSE()) -> 0 | BM6: =IF(SUM(BJ6:BL6)=3,1,0) -> 0
A7: =A6+1 -> 6 | B7: V | C7: E | D7: E | E7: =(IF($B7="V",1,0))+IF($C7="V",1,0)+IF($D7="V",1,0) -> 1 | F7: =(IF($B7="E",1,0))+IF($C7="E",1,0)+IF($D7="E",1,0) -> 2 | G7: =(IF($B7="O",1,0))+IF($C7="O",1,0)+IF($D7="O",1,0) -> 0 | H7: =(IF($B7="L",1,0))+IF($C7="L",1,0)+IF($D7="L",1,0) -> 0 | I7: =(IF(B7="V",1,0)) -> 1 | J7: =(IF(B7="E",1,0)) -> 0 | K7: =(IF(B7="O",1,0)) -> 0 | L7: =(IF(B7="L",1,0)) -> 0 | M7: =(IF(C7="V",1,0)) -> 0 | N7: =(IF(C7="E",1,0)) -> 1 | O7: =(IF(C7="O",1,0)) -> 0 | P7: =(IF(C7="L",1,0)) -> 0 | Q7: =(IF(D7="V",1,0)) -> 0 | R7: =(IF(D7="E",1,0)) -> 1 | S7: =(IF(D7="O",1,0)) -> 0 | T7: =(IF(D7="L",1,0)) -> 0 | U7: =MAX(E7-1,0) -> 0 | V7: =MAX(U7-1+F7,0) -> 1 | W7: =MAX(V7-1+G7,0) -> 0 | X7: =MAX(W7-1+H7,0) -> 0 | Y7: =0.5*(E7*I7+F7*J7+G7*K7+H7*L7-1)+(0+$U7*J7+$V7*K7+$W7*L7) -> 0 | Z7: =0.5*(E7*M7+F7*N7+G7*O7+H7*P7-1)+(0+$U7*N7+$V7*O7+$W7*P7) -> 0.5 | AA7: =0.5*(E7*Q7+F7*R7+G7*S7+H7*T7-1)+(0+$U7*R7+$V7*S7+$W7*T7) -> 0.5 | AB7: =IF(B7="V",-2,0)+IF(B7="E",-1,0)+IF(B7="O",0,0)+IF(B7="L",1,0)+Y7 -> -2 | AC7: =IF(C7="V",-2,0)+IF(C7="E",-1,0)+IF(C7="O",0,0)+IF(C7="L",1,0)+Z7 -> -0.5 | AD7: =IF(D7="V",-2,0)+IF(D7="E",-1,0)+IF(D7="O",0,0)+IF(D7="L",1,0)+AA7 -> -0.5 | AE7: =IF(B7="V",-2,0)+IF(B7="E",-1,0)+IF(B7="O",0,0)+IF(B7="L",1,0) -> -2 | AF7: =IF(B7="V",-2,0)+IF(B7="E",-1,0)+IF(B7="O",0,0)+IF(B7="L",1,0)+Y7 -> -2 | AG7: =IF(B7="V",-2,0)+IF(B7="E",-1,0)+IF(B7="O",0,0)+IF(B7="L",1,0)+Y7*2 -> -2 | AH7: =IF(C7="V",-2,0)+IF(C7="E",-1,0)+IF(C7="O",0,0)+IF(C7="L",1,0) -> -1 | AI7: =IF(C7="V",-2,0)+IF(C7="E",-1,0)+IF(C7="O",0,0)+IF(C7="L",1,0)+Z7 -> -0.5 | AJ7: =IF(C7="V",-2,0)+IF(C7="E",-1,0)+IF(C7="O",0,0)+IF(C7="L",1,0)+Z7*2 -> 0 | AK7: =IF(D7="V",-2,0)+IF(D7="E",-1,0)+IF(D7="O",0,0)+IF(D7="L",1,0) -> -1 | AL7: =IF(D7="V",-2,0)+IF(D7="E",-1,0)+IF(D7="O",0,0)+IF(D7="L",1,0)+AA7 -> -0.5 | AM7: =IF(D7="V",-2,0)+IF(D7="E",-1,0)+IF(D7="O",0,0)+IF(D7="L",1,0)+AA7*2 -> 0 | AN7: =(ABS(IF(AE7<0,AE7*Early,AE7*Late))+ABS(IF(AF7<0,AF7*Early,AF7*Late))+ABS(IF(AG7<0,AG7*Early,AG7*Late)))/3 -> 6 | AO7: =(ABS(IF(AH7<0,AH7*Early,AH7*Late))+ABS(IF(AI7<0,AI7*Early,AI7*Late))+ABS(IF(AJ7<0,AJ7*Early,AJ7*Late)))/3 -> 1.5 | AP7: =(ABS(IF(AK7<0,AK7*Early,AK7*Late))+ABS(IF(AL7<0,AL7*Early,AL7*Late))+ABS(IF(AM7<0,AM7*Early,AM7*Late)))/3 -> 1.5 | AQ7: =Y7*Delay+AN7 -> 6 | AR7: =Z7*Delay+AO7 -> 2 | AS7: =AA7*Delay+AP7 -> 2 | AT7: =VLOOKUP(A7,SortA!$A$1:$AT$65,46,FALSE()) -> 0 | AU7: =VLOOKUP(A7,SortB!$A$1:$AT$65,46,FALSE()) -> 0 | AV7: =VLOOKUP(A7,SortC!$A$1:$AT$65,46,FALSE()) -> 0 | AW7: =IF(SUM(AT7:AV7)=3,1,0) -> 0 | AX7: =B7&C7&D7 -> VEE | AY7: =AQ7+AR7+AS7 -> 10 | AZ7: =RIGHT(AX7,2) -> EE | BA7: =LEFT(AX7,1)&RIGHT(AX7,1) -> VE | BB7: =LEFT(AX7,2) -> VE | BC7: =VLOOKUP(AZ7,TwoPlayers!$AG$1:$AH$17,2,FALSE()) -> 4 | BD7: =VLOOKUP(BA7,TwoPlayers!$AG$1:$AH$17,2,FALSE()) -> 9 | BE7: =VLOOKUP(BB7,TwoPlayers!$AG$1:$AH$17,2,FALSE()) -> 9 | BF7: =$AY7-BC7 -> 6 | BG7: =$AY7-BD7 -> 1 | BH7: =$AY7-BE7 -> 1 | BI7: =AX7 -> VEE | BJ7: =VLOOKUP(A7,SortA!$A$1:$BM$65,65,FALSE()) -> 0 | BK7: =VLOOKUP(A7,SortB!$A$1:$BM$65,65,FALSE()) -> 0 | BL7: =VLOOKUP(A7,SortC!$A$1:$BM$65,65,FALSE()) -> 0 | BM7: =IF(SUM(BJ7:BL7)=3,1,0) -> 0
A8: =A7+1 -> 7 | B8: V | C8: E | D8: O | E8: =(IF($B8="V",1,0))+IF($C8="V",1,0)+IF($D8="V",1,0) -> 1 | F8: =(IF($B8="E",1,0))+IF($C8="E",1,0)+IF($D8="E",1,0) -> 1 | G8: =(IF($B8="O",1,0))+IF($C8="O",1,0)+IF($D8="O",1,0) -> 1 | H8: =(IF($B8="L",1,0))+IF($C8="L",1,0)+IF($D8="L",1,0) -> 0 | I8: =(IF(B8="V",1,0)) -> 1 | J8: =(IF(B8="E",1,0)) -> 0 | K8: =(IF(B8="O",1,0)) -> 0 | L8: =(IF(B8="L",1,0)) -> 0 | M8: =(IF(C8="V",1,0)) -> 0 | N8: =(IF(C8="E",1,0)) -> 1 | O8: =(IF(C8="O",1,0)) -> 0 | P8: =(IF(C8="L",1,0)) -> 0 | Q8: =(IF(D8="V",1,0)) -> 0 | R8: =(IF(D8="E",1,0)) -> 0 | S8: =(IF(D8="O",1,0)) -> 1 | T8: =(IF(D8="L",1,0)) -> 0 | U8: =MAX(E8-1,0) -> 0 | V8: =MAX(U8-1+F8,0) -> 0 | W8: =MAX(V8-1+G8,0) -> 0 | X8: =MAX(W8-1+H8,0) -> 0 | Y8: =0.5*(E8*I8+F8*J8+G8*K8+H8*L8-1)+(0+$U8*J8+$V8*K8+$W8*L8) -> 0 | Z8: =0.5*(E8*M8+F8*N8+G8*O8+H8*P8-1)+(0+$U8*N8+$V8*O8+$W8*P8) -> 0 | AA8: =0.5*(E8*Q8+F8*R8+G8*S8+H8*T8-1)+(0+$U8*R8+$V8*S8+$W8*T8) -> 0 | AB8: =IF(B8="V",-2,0)+IF(B8="E",-1,0)+IF(B8="O",0,0)+IF(B8="L",1,0)+Y8 -> -2 | AC8: =IF(C8="V",-2,0)+IF(C8="E",-1,0)+IF(C8="O",0,0)+IF(C8="L",1,0)+Z8 -> -1 | AD8: =IF(D8="V",-2,0)+IF(D8="E",-1,0)+IF(D8="O",0,0)+IF(D8="L",1,0)+AA8 -> 0 | AE8: =IF(B8="V",-2,0)+IF(B8="E",-1,0)+IF(B8="O",0,0)+IF(B8="L",1,0) -> -2 | AF8: =IF(B8="V",-2,0)+IF(B8="E",-1,0)+IF(B8="O",0,0)+IF(B8="L",1,0)+Y8 -> -2 | AG8: =IF(B8="V",-2,0)+IF(B8="E",-1,0)+IF(B8="O",0,0)+IF(B8="L",1,0)+Y8*2 -> -2 | AH8: =IF(C8="V",-2,0)+IF(C8="E",-1,0)+IF(C8="O",0,0)+IF(C8="L",1,0) -> -1 | AI8: =IF(C8="V",-2,0)+IF(C8="E",-1,0)+IF(C8="O",0,0)+IF(C8="L",1,0)+Z8 -> -1 | AJ8: =IF(C8="V",-2,0)+IF(C8="E",-1,0)+IF(C8="O",0,0)+IF(C8="L",1,0)+Z8*2 -> -1 | AK8: =IF(D8="V",-2,0)+IF(D8="E",-1,0)+IF(D8="O",0,0)+IF(D8="L",1,0) -> 0 | AL8: =IF(D8="V",-2,0)+IF(D8="E",-1,0)+IF(D8="O",0,0)+IF(D8="L",1,0)+AA8 -> 0 | AM8: =IF(D8="V",-2,0)+IF(D8="E",-1,0)+IF(D8="O",0,0)+IF(D8="L",1,0)+AA8*2 -> 0 | AN8: =(ABS(IF(AE8<0,AE8*Early,AE8*Late))+ABS(IF(AF8<0,AF8*Early,AF8*Late))+ABS(IF(AG8<0,AG8*Early,AG8*Late)))/3 -> 6 | AO8: =(ABS(IF(AH8<0,AH8*Early,AH8*Late))+ABS(IF(AI8<0,AI8*Early,AI8*Late))+ABS(IF(AJ8<0,AJ8*Early,AJ8*Late)))/3 -> 3 | AP8: =(ABS(IF(AK8<0,AK8*Early,AK8*Late))+ABS(IF(AL8<0,AL8*Early,AL8*Late))+ABS(IF(AM8<0,AM8*Early,AM8*Late)))/3 -> 0 | AQ8: =Y8*Delay+AN8 -> 6 | AR8: =Z8*Delay+AO8 -> 3 | AS8: =AA8*Delay+AP8 -> 0 | AT8: =VLOOKUP(A8,SortA!$A$1:$AT$65,46,FALSE()) -> 0 | AU8: =VLOOKUP(A8,SortB!$A$1:$AT$65,46,FALSE()) -> 0 | AV8: =VLOOKUP(A8,SortC!$A$1:$AT$65,46,FALSE()) -> 1 | AW8: =IF(SUM(AT8:AV8)=3,1,0) -> 0 | AX8: =B8&C8&D8 -> VEO | AY8: =AQ8+AR8+AS8 -> 9 | AZ8: =RIGHT(AX8,2) -> EO | BA8: =LEFT(AX8,1)&RIGHT(AX8,1) -> VO | BB8: =LEFT(AX8,2) -> VE | BC8: =VLOOKUP(AZ8,TwoPlayers!$AG$1:$AH$17,2,FALSE()) -> 3 | BD8: =VLOOKUP(BA8,TwoPlayers!$AG$1:$AH$17,2,FALSE()) -> 6 | BE8: =VLOOKUP(BB8,TwoPlayers!$AG$1:$AH$17,2,FALSE()) -> 9 | BF8: =$AY8-BC8 -> 6 | BG8: =$AY8-BD8 -> 3 | BH8: =$AY8-BE8 -> 0 | BI8: =AX8 -> VEO | BJ8: =VLOOKUP(A8,SortA!$A$1:$BM$65,65,FALSE()) -> 0 | BK8: =VLOOKUP(A8,SortB!$A$1:$BM$65,65,FALSE()) -> 1 | BL8: =VLOOKUP(A8,SortC!$A$1:$BM$65,65,FALSE()) -> 1 | BM8: =IF(SUM(BJ8:BL8)=3,1,0) -> 0
A9: =A8+1 -> 8 | B9: V | C9: E | D9: L | E9: =(IF($B9="V",1,0))+IF($C9="V",1,0)+IF($D9="V",1,0) -> 1 | F9: =(IF($B9="E",1,0))+IF($C9="E",1,0)+IF($D9="E",1,0) -> 1 | G9: =(IF($B9="O",1,0))+IF($C9="O",1,0)+IF($D9="O",1,0) -> 0 | H9: =(IF($B9="L",1,0))+IF($C9="L",1,0)+IF($D9="L",1,0) -> 1 | I9: =(IF(B9="V",1,0)) -> 1 | J9: =(IF(B9="E",1,0)) -> 0 | K9: =(IF(B9="O",1,0)) -> 0 | L9: =(IF(B9="L",1,0)) -> 0 | M9: =(IF(C9="V",1,0)) -> 0 | N9: =(IF(C9="E",1,0)) -> 1 | O9: =(IF(C9="O",1,0)) -> 0 | P9: =(IF(C9="L",1,0)) -> 0 | Q9: =(IF(D9="V",1,0)) -> 0 | R9: =(IF(D9="E",1,0)) -> 0 | S9: =(IF(D9="O",1,0)) -> 0 | T9: =(IF(D9="L",1,0)) -> 1 | U9: =MAX(E9-1,0) -> 0 | V9: =MAX(U9-1+F9,0) -> 0 | W9: =MAX(V9-1+G9,0) -> 0 | X9: =MAX(W9-1+H9,0) -> 0 | Y9: =0.5*(E9*I9+F9*J9+G9*K9+H9*L9-1)+(0+$U9*J9+$V9*K9+$W9*L9) -> 0 | Z9: =0.5*(E9*M9+F9*N9+G9*O9+H9*P9-1)+(0+$U9*N9+$V9*O9+$W9*P9) -> 0 | AA9: =0.5*(E9*Q9+F9*R9+G9*S9+H9*T9-1)+(0+$U9*R9+$V9*S9+$W9*T9) -> 0 | AB9: =IF(B9="V",-2,0)+IF(B9="E",-1,0)+IF(B9="O",0,0)+IF(B9="L",1,0)+Y9 -> -2 | AC9: =IF(C9="V",-2,0)+IF(C9="E",-1,0)+IF(C9="O",0,0)+IF(C9="L",1,0)+Z9 -> -1 | AD9: =IF(D9="V",-2,0)+IF(D9="E",-1,0)+IF(D9="O",0,0)+IF(D9="L",1,0)+AA9 -> 1 | AE9: =IF(B9="V",-2,0)+IF(B9="E",-1,0)+IF(B9="O",0,0)+IF(B9="L",1,0) -> -2 | AF9: =IF(B9="V",-2,0)+IF(B9="E",-1,0)+IF(B9="O",0,0)+IF(B9="L",1,0)+Y9 -> -2 | AG9: =IF(B9="V",-2,0)+IF(B9="E",-1,0)+IF(B9="O",0,0)+IF(B9="L",1,0)+Y9*2 -> -2 | AH9: =IF(C9="V",-2,0)+IF(C9="E",-1,0)+IF(C9="O",0,0)+IF(C9="L",1,0) -> -1 | AI9: =IF(C9="V",-2,0)+IF(C9="E",-1,0)+IF(C9="O",0,0)+IF(C9="L",1,0)+Z9 -> -1 | AJ9: =IF(C9="V",-2,0)+IF(C9="E",-1,0)+IF(C9="O",0,0)+IF(C9="L",1,0)+Z9*2 -> -1 | AK9: =IF(D9="V",-2,0)+IF(D9="E",-1,0)+IF(D9="O",0,0)+IF(D9="L",1,0) -> 1 | AL9: =IF(D9="V",-2,0)+IF(D9="E",-1,0)+IF(D9="O",0,0)+IF(D9="L",1,0)+AA9 -> 1 | AM9: =IF(D9="V",-2,0)+IF(D9="E",-1,0)+IF(D9="O",0,0)+IF(D9="L",1,0)+AA9*2 -> 1 | AN9: =(ABS(IF(AE9<0,AE9*Early,AE9*Late))+ABS(IF(AF9<0,AF9*Early,AF9*Late))+ABS(IF(AG9<0,AG9*Early,AG9*Late)))/3 -> 6 | AO9: =(ABS(IF(AH9<0,AH9*Early,AH9*Late))+ABS(IF(AI9<0,AI9*Early,AI9*Late))+ABS(IF(AJ9<0,AJ9*Early,AJ9*Late)))/3 -> 3 | AP9: =(ABS(IF(AK9<0,AK9*Early,AK9*Late))+ABS(IF(AL9<0,AL9*Early,AL9*Late))+ABS(IF(AM9<0,AM9*Early,AM9*Late)))/3 -> 4 | AQ9: =Y9*Delay+AN9 -> 6 | AR9: =Z9*Delay+AO9 -> 3 | AS9: =AA9*Delay+AP9 -> 4 | AT9: =VLOOKUP(A9,SortA!$A$1:$AT$65,46,FALSE()) -> 0 | AU9: =VLOOKUP(A9,SortB!$A$1:$AT$65,46,FALSE()) -> 0 | AV9: =VLOOKUP(A9,SortC!$A$1:$AT$65,46,FALSE()) -> 0 | AW9: =IF(SUM(AT9:AV9)=3,1,0) -> 0 | AX9: =B9&C9&D9 -> VEL | AY9: =AQ9+AR9+AS9 -> 13 | AZ9: =RIGHT(AX9,2) -> EL | BA9: =LEFT(AX9,1)&RIGHT(AX9,1) -> VL | BB9: =LEFT(AX9,2) -> VE | BC9: =VLOOKUP(AZ9,TwoPlayers!$AG$1:$AH$17,2,FALSE()) -> 7 | BD9: =VLOOKUP(BA9,TwoPlayers!$AG$1:$AH$17,2,FALSE()) -> 10 | BE9: =VLOOKUP(BB9,TwoPlayers!$AG$1:$AH$17,2,FALSE()) -> 9 | BF9: =$AY9-BC9 -> 6 | BG9: =$AY9-BD9 -> 3 | BH9: =$AY9-BE9 -> 4 | BI9: =AX9 -> VEL | BJ9: =VLOOKUP(A9,SortA!$A$1:$BM$65,65,FALSE()) -> 0 | BK9: =VLOOKUP(A9,SortB!$A$1:$BM$65,65,FALSE()) -> 0 | BL9: =VLOOKUP(A9,SortC!$A$1:$BM$65,65,FALSE()) -> 0 | BM9: =IF(SUM(BJ9:BL9)=3,1,0) -> 0
